Workbook

Sheet cement_plants_main
A1: id | B1: name | C1: lat | D1: lon | E1: type | F1: fuel | G1: region | H1: country | I1: status | J1: capacity_tonnes | K1: emfpm10 | L1: pm10_t_yr | M1: emfpm25 | N1: pm25_t_yr | O1: emfso2 | P1: so2_t_yr | Q1: emfnox | R1: nox_t_yr
A2: CMB-1 | B2: Heidelberg Cement Bangladesh Ltd - Kanchpur Plant | C2: 23.712851 | D2: 90.516048 | E2: grinding | G2: Dhaka Division | H2: Bangladesh | I2: operating | J2: 1500000 | K2: =Sheet1!$G$5 -> 0.0002223 | L2: =J2*K2 -> 333.45 | M2: =Sheet1!$G$2 -> 0.0001235 | N2: =J2*M2 -> 185.25 | O2: =Sheet1!$G$3 -> 0.0007695 | P2: =O2*J2 -> 1154.25 | Q2: =Sheet1!$G$4 -> 0.000494 | R2: =Q2*J2 -> 741
A3: CMB-2 | B3: LafargeHolcim Bangladesh Ltd | C3: 23.611005 | D3: 90.613007 | E3: grinding | G3: Dhaka Division | H3: Bangladesh | I3: operating | J3: 2707000 | K3: =Sheet1!$G$5 -> 0.0002223 | L3: =J3*K3 -> 601.7661 | M3: =Sheet1!$G$2 -> 0.0001235 | N3: =J3*M3 -> 334.3145 | O3: =Sheet1!$G$3 -> 0.0007695 | P3: =O3*J3 -> 2083.0365 | Q3: =Sheet1!$G$4 -> 0.000494 | R3: =Q3*J3 -> 1337.258
A4: CMB-3 | B4: LafargeHolcim Bangladesh Ltd | C4: 22.504972 | D4: 89.589503 | E4: grinding | G4: Khulna Division | H4: Bangladesh | I4: operating | J4: 200000 | K4: =Sheet1!$G$5 -> 0.0002223 | L4: =J4*K4 -> 44.46 | M4: =Sheet1!$G$2 -> 0.0001235 | N4: =J4*M4 -> 24.7 | O4: =Sheet1!$G$3 -> 0.0007695 | P4: =O4*J4 -> 153.9 | Q4: =Sheet1!$G$4 -> 0.000494 | R4: =Q4*J4 -> 98.8
A5: CMB-4 | B5: Shun Shing Cement Mills Ltd | C5: 22.317574 | D5: 91.867925 | E5: grinding | G5: Khulna Division | H5: Bangladesh | I5: operating | J5: 1500000 | K5: =Sheet1!$G$5 -> 0.0002223 | L5: =J5*K5 -> 333.45 | M5: =Sheet1!$G$2 -> 0.0001235 | N5: =J5*M5 -> 185.25 | O5: =Sheet1!$G$3 -> 0.0007695 | P5: =O5*J5 -> 1154.25 | Q5: =Sheet1!$G$4 -> 0.000494 | R5: =Q5*J5 -> 741
A6: CMB-5 | B6: Mongla Cement Factory | C6: 22.517902 | D6: 89.58562 | E6: grinding | G6: Khulna Division | H6: Bangladesh | I6: operating | J6: 1700000 | K6: =Sheet1!$G$5 -> 0.0002223 | L6: =J6*K6 -> 377.91 | M6: =Sheet1!$G$2 -> 0.0001235 | N6: =J6*M6 -> 209.95 | O6: =Sheet1!$G$3 -> 0.0007695 | P6: =O6*J6 -> 1308.15 | Q6: =Sheet1!$G$4 -> 0.000494 | R6: =Q6*J6 -> 839.8
A7: CMB-6 | B7: Crown Cement Factory Ltd. | C7: 23.576689 | D7: 90.508382 | E7: grinding | G7: Dhaka Division | H7: Bangladesh | I7: operating | J7: 4620000 | K7: =Sheet1!$G$5 -> 0.0002223 | L7: =J7*K7 -> 1027.026 | M7: =Sheet1!$G$2 -> 0.0001235 | N7: =J7*M7 -> 570.57 | O7: =Sheet1!$G$3 -> 0.0007695 | P7: =O7*J7 -> 3555.09 | Q7: =Sheet1!$G$4 -> 0.000494 | R7: =Q7*J7 -> 2282.28
A8: CMB-7 | B8: Elephant Brand Cement | C8: 22.517834 | D8: 89.585596 | E8: grinding | G8: Khulna Division | H8: Bangladesh | I8: operating | K8: =Sheet1!$G$5 -> 0.0002223 | L8: =J8*K8 -> 0 | M8: =Sheet1!$G$2 -> 0.0001235 | N8: =J8*M8 -> 0 | O8: =Sheet1!$G$3 -> 0.0007695 | P8: =O8*J8 -> 0 | Q8: =Sheet1!$G$4 -> 0.000494 | R8: =Q8*J8 -> 0
A9: CMB-8 | B9: Scan Cement Factory | C9: 23.568501 | D9: 90.520327 | E9: grinding | G9: Dhaka Division | H9: Bangladesh | I9: operating | J9: 700000 | K9: =Sheet1!$G$5 -> 0.0002223 | L9: =J9*K9 -> 155.61 | M9: =Sheet1!$G$2 -> 0.0001235 | N9: =J9*M9 -> 86.45 | O9: =Sheet1!$G$3 -> 0.0007695 | P9: =O9*J9 -> 538.65 | Q9: =Sheet1!$G$4 -> 0.000494 | R9: =Q9*J9 -> 345.8
A10: CMB-9 | B10: Five Rings Cement Industries | C10: 22.503884 | D10: 89.590302 | E10: grinding | G10: Khulna Division | H10: Bangladesh | I10: operating | K10: =Sheet1!$G$5 -> 0.0002223 | L10: =J10*K10 -> 0 | M10: =Sheet1!$G$2 -> 0.0001235 | N10: =J10*M10 -> 0 | O10: =Sheet1!$G$3 -> 0.0007695 | P10: =O10*J10 -> 0 | Q10: =Sheet1!$G$4 -> 0.000494 | R10: =Q10*J10 -> 0
A11: CMB-10 | B11: Anchor Cement Company | C11: 22.652466 | D11: 90.345293 | E11: grinding | G11: Barisal Division | H11: Bangladesh | I11: operating | J11: 1460000 | K11: =Sheet1!$G$5 -> 0.0002223 | L11: =J11*K11 -> 324.558 | M11: =Sheet1!$G$2 -> 0.0001235 | N11: =J11*M11 -> 180.31 | O11: =Sheet1!$G$3 -> 0.0007695 | P11: =O11*J11 -> 1123.47 | Q11: =Sheet1!$G$4 -> 0.000494 | R11: =Q11*J11 -> 721.24
A12: CMB-11 | B12: Shah Cement | C12: 23.568618 | D12: 90.524404 | E12: grinding | G12: Dhaka Division | H12: Bangladesh | I12: operating | J12: 1860000 | K12: =Sheet1!$G$5 -> 0.0002223 | L12: =J12*K12 -> 413.478 | M12: =Sheet1!$G$2 -> 0.0001235 | N12: =J12*M12 -> 229.71 | O12: =Sheet1!$G$3 -> 0.0007695 | P12: =O12*J12 -> 1431.27 | Q12: =Sheet1!$G$4 -> 0.000494 | R12: =Q12*J12 -> 918.84
A13: CMB-12 | B13: Premier cement mills 3/4 point | C13: 23.578555 | D13: 90.513202 | E13: grinding | G13: Dhaka Division | H13: Bangladesh | I13: operating | J13: 2400000 | K13: =Sheet1!$G$5 -> 0.0002223 | L13: =J13*K13 -> 533.52 | M13: =Sheet1!$G$2 -> 0.0001235 | N13: =J13*M13 -> 296.4 | O13: =Sheet1!$G$3 -> 0.0007695 | P13: =O13*J13 -> 1846.8 | Q13: =Sheet1!$G$4 -> 0.000494 | R13: =Q13*J13 -> 1185.6
A14: CMB-13 | B14: Anwar Cement Ltd.Plant | C14: 23.602161 | D14: 90.624685 | E14: grinding | G14: Dhaka Division | H14: Bangladesh | I14: operating | J14: 700000 | K14: =Sheet1!$G$5 -> 0.0002223 | L14: =J14*K14 -> 155.61 | M14: =Sheet1!$G$2 -> 0.0001235 | N14: =J14*M14 -> 86.45 | O14: =Sheet1!$G$3 -> 0.0007695 | P14: =O14*J14 -> 538.65 | Q14: =Sheet1!$G$4 -> 0.000494 | R14: =Q14*J14 -> 345.8
A15: CMB-14 | B15: Unique Cement Mills | C15: 23.609232 | D15: 90.61001 | E15: grinding | G15: Dhaka Division | H15: Bangladesh | I15: operating | K15: =Sheet1!$G$5 -> 0.0002223 | L15: =J15*K15 -> 0 | M15: =Sheet1!$G$2 -> 0.0001235 | N15: =J15*M15 -> 0 | O15: =Sheet1!$G$3 -> 0.0007695 | P15: =O15*J15 -> 0 | Q15: =Sheet1!$G$4 -> 0.000494 | R15: =Q15*J15 -> 0
A16: CMB-15 | B16: N/A | C16: 24.127959 | D16: 89.586911 | E16: grinding | G16: Rajshahi Division | H16: Bangladesh | I16: operating | K16: =Sheet1!$G$5 -> 0.0002223 | L16: =J16*K16 -> 0 | M16: =Sheet1!$G$2 -> 0.0001235 | N16: =J16*M16 -> 0 | O16: =Sheet1!$G$3 -> 0.0007695 | P16: =O16*J16 -> 0 | Q16: =Sheet1!$G$4 -> 0.000494 | R16: =Q16*J16 -> 0
A17: CMB-16 | B17: Aman Cement Mills Ltd. | C17: 24.290893 | D17: 89.566546 | E17: grinding | G17: Rajshahi Division | H17: Bangladesh | I17: operating | J17: 750000 | K17: =Sheet1!$G$5 -> 0.0002223 | L17: =J17*K17 -> 166.725 | M17: =Sheet1!$G$2 -> 0.0001235 | N17: =J17*M17 -> 92.625 | O17: =Sheet1!$G$3 -> 0.0007695 | P17: =O17*J17 -> 577.125 | Q17: =Sheet1!$G$4 -> 0.000494 | R17: =Q17*J17 -> 370.5
A18: CMB-17 | B18: Shun Shing Cement Mills Ltd (Plant 2) | C18: 22.317574 | D18: 91.867925 | E18: grinding | G18: Chittagong | H18: Bangladesh | I18: operating | J18: 3450000 | K18: =Sheet1!$G$5 -> 0.0002223 | L18: =J18*K18 -> 766.935 | M18: =Sheet1!$G$2 -> 0.0001235 | N18: =J18*M18 -> 426.075 | O18: =Sheet1!$G$3 -> 0.0007695 | P18: =O18*J18 -> 2654.775 | Q18: =Sheet1!$G$4 -> 0.000494 | R18: =Q18*J18 -> 1704.3
A19: CMB-18 | B19: Shun Shing Cement Mills Ltd (Plant 3) | C19: 23.934081 | D19: 90.613085 | E19: grinding | G19: Dhaka Division | H19: Bangladesh | I19: operating | J19: 3450000 | K19: =Sheet1!$G$5 -> 0.0002223 | L19: =J19*K19 -> 766.935 | M19: =Sheet1!$G$2 -> 0.0001235 | N19: =J19*M19 -> 426.075 | O19: =Sheet1!$G$3 -> 0.0007695 | P19: =O19*J19 -> 2654.775 | Q19: =Sheet1!$G$4 -> 0.000494 | R19: =Q19*J19 -> 1704.3
A20: CMB-19 | B20: Heidelberg Materials Bangladesh PLC. - Chattogram Plant | C20: 22.278973 | D20: 91.785257 | E20: grinding | G20: Chittagong | H20: Bangladesh | I20: operating | J20: 1300000 | K20: =Sheet1!$G$5 -> 0.0002223 | L20: =J20*K20 -> 288.99 | M20: =Sheet1!$G$2 -> 0.0001235 | N20: =J20*M20 -> 160.55 | O20: =Sheet1!$G$3 -> 0.0007695 | P20: =O20*J20 -> 1000.35 | Q20: =Sheet1!$G$4 -> 0.000494 | R20: =Q20*J20 -> 642.2
A21: CMB-20 | B21: Heidelberg Cement Bangladesh Ltd - Munshiganj Plant | C21: 23.568661 | D21: 90.520632 | E21: grinding | G21: Dhaka Division | H21: Bangladesh | I21: operating | J21: 600000 | K21: =Sheet1!$G$5 -> 0.0002223 | L21: =J21*K21 -> 133.38 | M21: =Sheet1!$G$2 -> 0.0001235 | N21: =J21*M21 -> 74.1 | O21: =Sheet1!$G$3 -> 0.0007695 | P21: =O21*J21 -> 461.7 | Q21: =Sheet1!$G$4 -> 0.000494 | R21: =Q21*J21 -> 296.4
A22: CMI-3 | B22: RCCPL Pvt Ltd | C22: 26.404843 | D22: 81.130322 | E22: grinding | G22: Uttar Pradesh | H22: India | I22: operating | J22: =2*1000000 -> 2000000 | K22: =Sheet1!$G$5 -> 0.0002223 | L22: =J22*K22 -> 444.6 | M22: =Sheet1!$G$2 -> 0.0001235 | N22: =J22*M22 -> 247 | O22: =Sheet1!$G$3 -> 0.0007695 | P22: =O22*J22 -> 1539 | Q22: =Sheet1!$G$4 -> 0.000494 | R22: =Q22*J22 -> 988
A23: CMI-4 | B23: ACC Ltd | C23: 26.190592 | D23: 81.706283 | E23: grinding | G23: Uttar Pradesh | H23: India | I23: operating | J23: 0 | K23: =Sheet1!$G$5 -> 0.0002223 | L23: =J23*K23 -> 0 | M23: =Sheet1!$G$2 -> 0.0001235 | N23: =J23*M23 -> 0 | O23: =Sheet1!$G$3 -> 0.0007695 | P23: =O23*J23 -> 0 | Q23: =Sheet1!$G$4 -> 0.000494 | R23: =Q23*J23 -> 0
A24: CMI-5 | B24: Ambuja Cements Ltd | C24: 30.233638 | D24: 74.912213 | E24: grinding | G24: Punjab | H24: India | I24: operating | J24: 0 | K24: =Sheet1!$G$5 -> 0.0002223 | L24: =J24*K24 -> 0 | M24: =Sheet1!$G$2 -> 0.0001235 | N24: =J24*M24 -> 0 | O24: =Sheet1!$G$3 -> 0.0007695 | P24: =O24*J24 -> 0 | Q24: =Sheet1!$G$4 -> 0.000494 | R24: =Q24*J24 -> 0
A25: CMI-6 | B25: Ambuja Cements Ltd | C25: 28.570512 | D25: 77.546556 | E25: grinding | G25: Uttar Pradesh | H25: India | I25: operating | J25: 0 | K25: =Sheet1!$G$5 -> 0.0002223 | L25: =J25*K25 -> 0 | M25: =Sheet1!$G$2 -> 0.0001235 | N25: =J25*M25 -> 0 | O25: =Sheet1!$G$3 -> 0.0007695 | P25: =O25*J25 -> 0 | Q25: =Sheet1!$G$4 -> 0.000494 | R25: =Q25*J25 -> 0
A26: CMI-7 | B26: Ambuja Cements Ltd | C26: 22.569254 | D26: 88.194228 | E26: grinding | G26: West Bengal | H26: India | I26: operating | J26: 0 | K26: =Sheet1!$G$5 -> 0.0002223 | L26: =J26*K26 -> 0 | M26: =Sheet1!$G$2 -> 0.0001235 | N26: =J26*M26 -> 0 | O26: =Sheet1!$G$3 -> 0.0007695 | P26: =O26*J26 -> 0 | Q26: =Sheet1!$G$4 -> 0.000494 | R26: =Q26*J26 -> 0
A27: CMI-8 | B27: Ambuja Cements Ltd | C27: 29.967487 | D27: 77.769868 | E27: grinding | G27: Uttarakhand | H27: India | I27: operating | J27: 0 | K27: =Sheet1!$G$5 -> 0.0002223 | L27: =J27*K27 -> 0 | M27: =Sheet1!$G$2 -> 0.0001235 | N27: =J27*M27 -> 0 | O27: =Sheet1!$G$3 -> 0.0007695 | P27: =O27*J27 -> 0 | Q27: =Sheet1!$G$4 -> 0.000494 | R27: =Q27*J27 -> 0
A28: CMI-9 | B28: Ambuja Cements Ltd | C28: 24.775292 | D28: 87.88645 | E28: grinding | G28: West Bengal | H28: India | I28: operating | J28: 0 | K28: =Sheet1!$G$5 -> 0.0002223 | L28: =J28*K28 -> 0 | M28: =Sheet1!$G$2 -> 0.0001235 | N28: =J28*M28 -> 0 | O28: =Sheet1!$G$3 -> 0.0007695 | P28: =O28*J28 -> 0 | Q28: =Sheet1!$G$4 -> 0.000494 | R28: =Q28*J28 -> 0
A29: CMI-10 | B29: Century Cement | C29: 24.388462 | D29: 88.083237 | E29: grinding | G29: West Bengal | H29: India | I29: operating | J29: =2*1000000 -> 2000000 | K29: =Sheet1!$G$5 -> 0.0002223 | L29: =J29*K29 -> 444.6 | M29: =Sheet1!$G$2 -> 0.0001235 | N29: =J29*M29 -> 247 | O29: =Sheet1!$G$3 -> 0.0007695 | P29: =O29*J29 -> 1539 | Q29: =Sheet1!$G$4 -> 0.000494 | R29: =Q29*J29 -> 988
A30: CMI-11 | B30: Nu Vista Ltd | C30: 23.439328 | D30: 87.51119 | E30: grinding | G30: West Bengal | H30: India | I30: operating | J30: =2.5*1000000 -> 2500000 | K30: =Sheet1!$G$5 -> 0.0002223 | L30: =J30*K30 -> 555.75 | M30: =Sheet1!$G$2 -> 0.0001235 | N30: =J30*M30 -> 308.75 | O30: =Sheet1!$G$3 -> 0.0007695 | P30: =O30*J30 -> 1923.75 | Q30: =Sheet1!$G$4 -> 0.000494 | R30: =Q30*J30 -> 1235
A31: CMI-12 | B31: Nuvoco Vistas Corporation Ltd | C31: 23.461907 | D31: 87.120726 | E31: grinding | G31: West Bengal | H31: India | I31: operating | J31: 0 | K31: =Sheet1!$G$5 -> 0.0002223 | L31: =J31*K31 -> 0 | M31: =Sheet1!$G$2 -> 0.0001235 | N31: =J31*M31 -> 0 | O31: =Sheet1!$G$3 -> 0.0007695 | P31: =O31*J31 -> 0 | Q31: =Sheet1!$G$4 -> 0.000494 | R31: =Q31*J31 -> 0
A32: CMI-13 | B32: Kalyanpur Cements Ltd | C32: 24.670568 | D32: 83.9891 | E32: integrated | G32: Bihar | H32: India | I32: operating | J32: 0 | K32: =Sheet1!$G$5 -> 0.0002223 | L32: =J32*K32 -> 0 | M32: =Sheet1!$G$2 -> 0.0001235 | N32: =J32*M32 -> 0 | O32: =Sheet1!$G$3 -> 0.0007695 | P32: =O32*J32 -> 0 | Q32: =Sheet1!$G$4 -> 0.000494 | R32: =Q32*J32 -> 0
A33: CMI-14 | B33: Nuvoco Vistas Corporation Ltd | C33: 28.455175 | D33: 76.273575 | E33: grinding | G33: Haryana | H33: India | I33: operating | J33: 0 | K33: =Sheet1!$G$5 -> 0.0002223 | L33: =J33*K33 -> 0 | M33: =Sheet1!$G$2 -> 0.0001235 | N33: =J33*M33 -> 0 | O33: =Sheet1!$G$3 -> 0.0007695 | P33: =O33*J33 -> 0 | Q33: =Sheet1!$G$4 -> 0.000494 | R33: =Q33*J33 -> 0
A34: CMI-15 | B34: Nu Vista Ltd | C34: 25.223534 | D34: 83.461625 | E34: grinding | G34: Bihar | H34: India | I34: operating | J34: =0.8*1000000 -> 800000 | K34: =Sheet1!$G$5 -> 0.0002223 | L34: =J34*K34 -> 177.84 | M34: =Sheet1!$G$2 -> 0.0001235 | N34: =J34*M34 -> 98.8 | O34: =Sheet1!$G$3 -> 0.0007695 | P34: =O34*J34 -> 615.6 | Q34: =Sheet1!$G$4 -> 0.000494 | R34: =Q34*J34 -> 395.2
A35: CMI-16 | B35: OCL India Ltd | C35: 22.528774 | D35: 87.313274 | E35: grinding | G35: West Bengal | H35: India | I35: operating | J35: 0 | K35: =Sheet1!$G$5 -> 0.0002223 | L35: =J35*K35 -> 0 | M35: =Sheet1!$G$2 -> 0.0001235 | N35: =J35*M35 -> 0 | O35: =Sheet1!$G$3 -> 0.0007695 | P35: =O35*J35 -> 0 | Q35: =Sheet1!$G$4 -> 0.000494 | R35: =Q35*J35 -> 0
A36: CMI-17 | B36: Ramco Cements Ltd | C36: 22.423362 | D36: 87.862852 | E36: grinding | G36: West Bengal | H36: India | I36: operating | J36: =1.95*1000000 -> 1950000 | K36: =Sheet1!$G$5 -> 0.0002223 | L36: =J36*K36 -> 433.485 | M36: =Sheet1!$G$2 -> 0.0001235 | N36: =J36*M36 -> 240.825 | O36: =Sheet1!$G$3 -> 0.0007695 | P36: =O36*J36 -> 1500.525 | Q36: =Sheet1!$G$4 -> 0.000494 | R36: =Q36*J36 -> 963.3
A37: CMI-18 | B37: J K Cement Ltd | C37: 28.490245 | D37: 76.386299 | E37: grinding | G37: Haryana | H37: India | I37: operating | J37: 0 | K37: =Sheet1!$G$5 -> 0.0002223 | L37: =J37*K37 -> 0 | M37: =Sheet1!$G$2 -> 0.0001235 | N37: =J37*M37 -> 0 | O37: =Sheet1!$G$3 -> 0.0007695 | P37: =O37*J37 -> 0 | Q37: =Sheet1!$G$4 -> 0.000494 | R37: =Q37*J37 -> 0
A38: CMI-19 | B38: Shree Cement Ltd | C38: 29.758381 | D38: 78.062049 | E38: grinding | G38: Uttarakhand | H38: India | I38: operating | J38: 0 | K38: =Sheet1!$G$5 -> 0.0002223 | L38: =J38*K38 -> 0 | M38: =Sheet1!$G$2 -> 0.0001235 | N38: =J38*M38 -> 0 | O38: =Sheet1!$G$3 -> 0.0007695 | P38: =O38*J38 -> 0 | Q38: =Sheet1!$G$4 -> 0.000494 | R38: =Q38*J38 -> 0
A39: CMI-20 | B39: JK Lakshmi Cement Ltd | C39: 28.495111 | D39: 76.358152 | E39: grinding | G39: Haryana | H39: India | I39: operating | J39: 0 | K39: =Sheet1!$G$5 -> 0.0002223 | L39: =J39*K39 -> 0 | M39: =Sheet1!$G$2 -> 0.0001235 | N39: =J39*M39 -> 0 | O39: =Sheet1!$G$3 -> 0.0007695 | P39: =O39*J39 -> 0 | Q39: =Sheet1!$G$4 -> 0.000494 | R39: =Q39*J39 -> 0
A40: CMI-21 | B40: Shree Cement Ltd | C40: 24.774342 | D40: 84.354352 | E40: grinding | G40: Bihar | H40: India | I40: operating | J40: 0 | K40: =Sheet1!$G$5 -> 0.0002223 | L40: =J40*K40 -> 0 | M40: =Sheet1!$G$2 -> 0.0001235 | N40: =J40*M40 -> 0 | O40: =Sheet1!$G$3 -> 0.0007695 | P40: =O40*J40 -> 0 | Q40: =Sheet1!$G$4 -> 0.000494 | R40: =Q40*J40 -> 0
...

Sheet Sheet1
A1: Pollutant | B1: EF_clinker | C1: Unit | D1: Type | E1: Clinker factor* | F1: EF_cement (g/tonnes of cement) | G1: EF_cement (tonnes of pollutant/tonnes of cement) | H1: Notes
A2: PM2.5 | B2: 130 | C2: g/tonnes | D2: Grinding | E2: 0.95 | F2: =E2*B2 -> 123.5 | G2: =F2/1000000 -> 0.0001235
A3: SO2** | B3: 810 | C3: g/tonnes | D3: Grinding | E3: 0.95 | F3: =E3*B3 -> 769.5 | G3: =F3/1000000 -> 0.0007695
A4: NOx** | B4: 520 | C4: g/tonnes | D4: Grinding | E4: 0.95 | F4: =E4*B4 -> 494 | G4: =F4/1000000 -> 0.000494
A5: PM10 | B5: 234 | C5: g/tonnes | D5: Grinding | E5: 0.95 | F5: =E5*B5 -> 222.3 | G5: =F5/1000000 -> 0.0002223
A6: TSP | B6: 260 | C6: g/tonnes | D6: Grinding | E6: 0.95 | F6: =E6*B6 -> 247 | G6: =F6/1000000 -> 0.000247
A7: BC | B7: 3 | C7: g/tonnes | D7: Grinding | E7: 0.95 | F7: =E7*B7 -> 2.85 | G7: =F7/1000000 -> 2.85e-06
A8: *Clinker factor: ratio of clinker mass to cement mass
A9: ** Median values used from Best available techniques
A10: Source: PM2.5, PM10, TSP, BC | B10: https://www.eea.europa.eu/en/analysis/publications/emep-eea-guidebook-2023/part-b-sectoral-guidance-chapters/2-industrial-processes-and-product-use/2-a-mineral-products/2-a-1-cement-production-2023/@@download/file | J10: 1000000
A11: Source: Best available techniques for SO2 and NOx | B11: https://unece.org/fileadmin/DAM/env/documents/2020/AIR/WGSR/TFTEI_Cement_final_document-december-2020.pdf
