Workbook

Sheet steel_plants_main
A1: id | B1: name | C1: lat | D1: lon | E1: type | F1: fuel | G1: region | H1: country | I1: status | J1: capacity_tonnes | K1: emfpm10 | L1: pm10_t_yr | M1: emfpm25 | N1: pm25_t_yr | O1: emfso2 | P1: so2_t_yr | Q1: emfnox | R1: nox_t_yr
A2: SPB-1 | B2: Abul Khair Ltd | C2: 22.444118 | D2: 91.740169 | E2: Downstream | G2: Chittagong Division | H2: Bangladesh | I2: Operating | J2: 750000 | K2: =Sheet1!$D$5 -> 0.00381 | L2: =J2*K2 -> 2857.5 | M2: =Sheet1!$D$2 -> 0.00251 | N2: =J2*M2 -> 1882.5 | O2: =Sheet1!$D$3 -> 0.00144 | P2: =J2*O2 -> 1080 | Q2: =Sheet1!$D$4 -> 0.00047 | R2: =Q2*J2 -> 352.5
A3: SPB-2 | B3: Abul Khair Ltd | C3: 22.472008 | D3: 91.734827 | E3: Mini-Mill | G3: Chittagong Division | H3: Bangladesh | I3: Operating | J3: 1400000 | K3: =Sheet1!$D$5 -> 0.00381 | L3: =J3*K3 -> 5334 | M3: =Sheet1!$D$2 -> 0.00251 | N3: =J3*M3 -> 3514 | O3: =Sheet1!$D$3 -> 0.00144 | P3: =J3*O3 -> 2016 | Q3: =Sheet1!$D$4 -> 0.00047 | R3: =Q3*J3 -> 658
A4: SPB-3 | B4: BSRM Steels Ltd | C4: 22.38106 | D4: 91.76862 | E4: Downstream | G4: Chittagong Division | H4: Bangladesh | I4: Operating | K4: =Sheet1!$D$5 -> 0.00381 | L4: =J4*K4 -> 0 | M4: =Sheet1!$D$2 -> 0.00251 | N4: =J4*M4 -> 0 | O4: =Sheet1!$D$3 -> 0.00144 | P4: =J4*O4 -> 0 | Q4: =Sheet1!$D$4 -> 0.00047 | R4: =Q4*J4 -> 0
A5: SPB-4 | B5: BSRM Steels Ltd | C5: 22.383964 | D5: 91.81024 | E5: Downstream | G5: Chittagong Division | H5: Bangladesh | I5: Operating | J5: 450000 | K5: =Sheet1!$D$5 -> 0.00381 | L5: =J5*K5 -> 1714.5 | M5: =Sheet1!$D$2 -> 0.00251 | N5: =J5*M5 -> 1129.5 | O5: =Sheet1!$D$3 -> 0.00144 | P5: =J5*O5 -> 648 | Q5: =Sheet1!$D$4 -> 0.00047 | R5: =Q5*J5 -> 211.5
A6: SPB-5 | B6: BSRM Steels Ltd | C6: 22.87176 | D6: 91.546568 | E6: Mini-Mill | G6: Chittagong Division | H6: Bangladesh | I6: Operating | J6: 700000 | K6: =Sheet1!$D$5 -> 0.00381 | L6: =J6*K6 -> 2667 | M6: =Sheet1!$D$2 -> 0.00251 | N6: =J6*M6 -> 1757 | O6: =Sheet1!$D$3 -> 0.00144 | P6: =J6*O6 -> 1008 | Q6: =Sheet1!$D$4 -> 0.00047 | R6: =Q6*J6 -> 329
A7: SPB-6 | B7: KY Steel | C7: 22.499834 | D7: 91.715778 | G7: Chittagong Division | H7: Bangladesh | I7: Operating | K7: =Sheet1!$D$5 -> 0.00381 | L7: =J7*K7 -> 0 | M7: =Sheet1!$D$2 -> 0.00251 | N7: =J7*M7 -> 0 | O7: =Sheet1!$D$3 -> 0.00144 | P7: =J7*O7 -> 0 | Q7: =Sheet1!$D$4 -> 0.00047 | R7: =Q7*J7 -> 0
A8: SPB-7 | B8: Kabir Steel Rolling Mills (KSRM) | C8: 22.501431 | D8: 91.714041 | G8: Chittagong Division | H8: Bangladesh | I8: Operating | J8: 800000 | K8: =Sheet1!$D$5 -> 0.00381 | L8: =J8*K8 -> 3048 | M8: =Sheet1!$D$2 -> 0.00251 | N8: =J8*M8 -> 2008 | O8: =Sheet1!$D$3 -> 0.00144 | P8: =J8*O8 -> 1152 | Q8: =Sheet1!$D$4 -> 0.00047 | R8: =Q8*J8 -> 376
A9: SPB-8 | B9: GPH Steel | C9: 22.536569 | D9: 91.700729 | G9: Chittagong Division | H9: Bangladesh | I9: Operating | J9: 1051000 | K9: =Sheet1!$D$5 -> 0.00381 | L9: =J9*K9 -> 4004.31 | M9: =Sheet1!$D$2 -> 0.00251 | N9: =J9*M9 -> 2638.01 | O9: =Sheet1!$D$3 -> 0.00144 | P9: =J9*O9 -> 1513.44 | Q9: =Sheet1!$D$4 -> 0.00047 | R9: =Q9*J9 -> 493.97
A10: SPI-1 | B10: Jindal Stainless Ltd | C10: 29.127253 | D10: 75.773075 | G10: Haryana | H10: India | I10: Operating | K10: =Sheet1!$D$5 -> 0.00381 | L10: =J10*K10 -> 0 | M10: =Sheet1!$D$2 -> 0.00251 | N10: =J10*M10 -> 0 | O10: =Sheet1!$D$3 -> 0.00144 | P10: =J10*O10 -> 0 | Q10: =Sheet1!$D$4 -> 0.00047 | R10: =Q10*J10 -> 0
A11: SPI-2 | B11: KR Steel Union Ltd | C11: 22.976512 | D11: 88.46118 | G11: West Bengal | H11: India | I11: Operating | K11: =Sheet1!$D$5 -> 0.00381 | L11: =J11*K11 -> 0 | M11: =Sheet1!$D$2 -> 0.00251 | N11: =J11*M11 -> 0 | O11: =Sheet1!$D$3 -> 0.00144 | P11: =J11*O11 -> 0 | Q11: =Sheet1!$D$4 -> 0.00047 | R11: =Q11*J11 -> 0
A12: SPI-3 | B12: Orissa Metaliks Pvt Ltd | C12: 22.378355 | D12: 87.281773 | E12: Integrated | G12: West Bengal | H12: India | I12: Operating | J12: =0.99*1000000 -> 990000 | K12: =Sheet1!$D$5 -> 0.00381 | L12: =J12*K12 -> 3771.9 | M12: =Sheet1!$D$2 -> 0.00251 | N12: =J12*M12 -> 2484.9 | O12: =Sheet1!$D$3 -> 0.00144 | P12: =J12*O12 -> 1425.6 | Q12: =Sheet1!$D$4 -> 0.00047 | R12: =Q12*J12 -> 465.3
A13: SPI-4 | B13: Steel Authority of India Ltd | C13: 23.665198 | D13: 86.917455 | E13: Integrated | G13: West Bengal | H13: India | I13: Operating | K13: =Sheet1!$D$5 -> 0.00381 | L13: =J13*K13 -> 0 | M13: =Sheet1!$D$2 -> 0.00251 | N13: =J13*M13 -> 0 | O13: =Sheet1!$D$3 -> 0.00144 | P13: =J13*O13 -> 0 | Q13: =Sheet1!$D$4 -> 0.00047 | R13: =Q13*J13 -> 0
A14: SPI-5 | B14: Steel Authority of India Ltd | C14: 23.546442 | D14: 87.249552 | E14: Integrated | G14: West Bengal | H14: India | I14: Operating | K14: =Sheet1!$D$5 -> 0.00381 | L14: =J14*K14 -> 0 | M14: =Sheet1!$D$2 -> 0.00251 | N14: =J14*M14 -> 0 | O14: =Sheet1!$D$3 -> 0.00144 | P14: =J14*O14 -> 0 | Q14: =Sheet1!$D$4 -> 0.00047 | R14: =Q14*J14 -> 0
A15: SPI-6 | B15: Steel Authority of India Ltd | C15: 23.522882 | D15: 87.275935 | G15: West Bengal | H15: India | I15: Operating | K15: =Sheet1!$D$5 -> 0.00381 | L15: =J15*K15 -> 0 | M15: =Sheet1!$D$2 -> 0.00251 | N15: =J15*M15 -> 0 | O15: =Sheet1!$D$3 -> 0.00144 | P15: =J15*O15 -> 0 | Q15: =Sheet1!$D$4 -> 0.00047 | R15: =Q15*J15 -> 0
A16: SPI-7 | B16: Tata Steel Ltd | C16: 22.385611 | D16: 87.287179 | E16: Integrated | G16: West Bengal | H16: India | I16: Operating | K16: =Sheet1!$D$5 -> 0.00381 | L16: =J16*K16 -> 0 | M16: =Sheet1!$D$2 -> 0.00251 | N16: =J16*M16 -> 0 | O16: =Sheet1!$D$3 -> 0.00144 | P16: =J16*O16 -> 0 | Q16: =Sheet1!$D$4 -> 0.00047 | R16: =Q16*J16 -> 0
A17: SPI-8 | B17: Tata Steel Ltd | C17: 28.648921 | D17: 77.331907 | G17: Uttar Pradesh | H17: India | I17: Operating | K17: =Sheet1!$D$5 -> 0.00381 | L17: =J17*K17 -> 0 | M17: =Sheet1!$D$2 -> 0.00251 | N17: =J17*M17 -> 0 | O17: =Sheet1!$D$3 -> 0.00144 | P17: =J17*O17 -> 0 | Q17: =Sheet1!$D$4 -> 0.00047 | R17: =Q17*J17 -> 0
A18: SPI-9 | B18: Usha Martin Ltd | C18: 31.583478 | D18: 75.95079 | G18: Punjab | H18: India | I18: Operating | K18: =Sheet1!$D$5 -> 0.00381 | L18: =J18*K18 -> 0 | M18: =Sheet1!$D$2 -> 0.00251 | N18: =J18*M18 -> 0 | O18: =Sheet1!$D$3 -> 0.00144 | P18: =J18*O18 -> 0 | Q18: =Sheet1!$D$4 -> 0.00047 | R18: =Q18*J18 -> 0
A19: SPI-10 | C19: 26.581306 | D19: 80.560423 | G19: Uttar Pradesh | H19: India | I19: Operating | K19: =Sheet1!$D$5 -> 0.00381 | L19: =J19*K19 -> 0 | M19: =Sheet1!$D$2 -> 0.00251 | N19: =J19*M19 -> 0 | O19: =Sheet1!$D$3 -> 0.00144 | P19: =J19*O19 -> 0 | Q19: =Sheet1!$D$4 -> 0.00047 | R19: =Q19*J19 -> 0
A20: SPI-11 | C20: 26.561084 | D20: 80.532491 | G20: Uttar Pradesh | H20: India | I20: Operating | K20: =Sheet1!$D$5 -> 0.00381 | L20: =J20*K20 -> 0 | M20: =Sheet1!$D$2 -> 0.00251 | N20: =J20*M20 -> 0 | O20: =Sheet1!$D$3 -> 0.00144 | P20: =J20*O20 -> 0 | Q20: =Sheet1!$D$4 -> 0.00047 | R20: =Q20*J20 -> 0
A21: SPI-12 | C21: 23.776213 | D21: 86.866906 | G21: West Bengal | H21: India | I21: Operating | K21: =Sheet1!$D$5 -> 0.00381 | L21: =J21*K21 -> 0 | M21: =Sheet1!$D$2 -> 0.00251 | N21: =J21*M21 -> 0 | O21: =Sheet1!$D$3 -> 0.00144 | P21: =J21*O21 -> 0 | Q21: =Sheet1!$D$4 -> 0.00047 | R21: =Q21*J21 -> 0
A22: SPI-13 | C22: 22.054668 | D22: 88.126162 | G22: West Bengal | H22: India | I22: Operating | K22: =Sheet1!$D$5 -> 0.00381 | L22: =J22*K22 -> 0 | M22: =Sheet1!$D$2 -> 0.00251 | N22: =J22*M22 -> 0 | O22: =Sheet1!$D$3 -> 0.00144 | P22: =J22*O22 -> 0 | Q22: =Sheet1!$D$4 -> 0.00047 | R22: =Q22*J22 -> 0
A23: SPI-14 | C23: 22.715728 | D23: 88.372253 | G23: West Bengal | H23: India | I23: Operating | K23: =Sheet1!$D$5 -> 0.00381 | L23: =J23*K23 -> 0 | M23: =Sheet1!$D$2 -> 0.00251 | N23: =J23*M23 -> 0 | O23: =Sheet1!$D$3 -> 0.00144 | P23: =J23*O23 -> 0 | Q23: =Sheet1!$D$4 -> 0.00047 | R23: =Q23*J23 -> 0
A24: SPI-15 | C24: 22.635024 | D24: 88.337702 | G24: West Bengal | H24: India | I24: Operating | K24: =Sheet1!$D$5 -> 0.00381 | L24: =J24*K24 -> 0 | M24: =Sheet1!$D$2 -> 0.00251 | N24: =J24*M24 -> 0 | O24: =Sheet1!$D$3 -> 0.00144 | P24: =J24*O24 -> 0 | Q24: =Sheet1!$D$4 -> 0.00047 | R24: =Q24*J24 -> 0
A25: SPI-16 | C25: 28.097508 | D25: 76.58241 | G25: Haryana | H25: India | I25: Operating | K25: =Sheet1!$D$5 -> 0.00381 | L25: =J25*K25 -> 0 | M25: =Sheet1!$D$2 -> 0.00251 | N25: =J25*M25 -> 0 | O25: =Sheet1!$D$3 -> 0.00144 | P25: =J25*O25 -> 0 | Q25: =Sheet1!$D$4 -> 0.00047 | R25: =Q25*J25 -> 0
A26: SPI-17 | C26: 28.734516 | D26: 76.842644 | G26: Haryana | H26: India | I26: Operating | K26: =Sheet1!$D$5 -> 0.00381 | L26: =J26*K26 -> 0 | M26: =Sheet1!$D$2 -> 0.00251 | N26: =J26*M26 -> 0 | O26: =Sheet1!$D$3 -> 0.00144 | P26: =J26*O26 -> 0 | Q26: =Sheet1!$D$4 -> 0.00047 | R26: =Q26*J26 -> 0
A27: SPI-18 | C27: 30.651464 | D27: 76.317017 | G27: Punjab | H27: India | I27: Operating | K27: =Sheet1!$D$5 -> 0.00381 | L27: =J27*K27 -> 0 | M27: =Sheet1!$D$2 -> 0.00251 | N27: =J27*M27 -> 0 | O27: =Sheet1!$D$3 -> 0.00144 | P27: =J27*O27 -> 0 | Q27: =Sheet1!$D$4 -> 0.00047 | R27: =Q27*J27 -> 0
A28: SPI-19 | C28: 30.845731 | D28: 75.960442 | G28: Punjab | H28: India | I28: Operating | K28: =Sheet1!$D$5 -> 0.00381 | L28: =J28*K28 -> 0 | M28: =Sheet1!$D$2 -> 0.00251 | N28: =J28*M28 -> 0 | O28: =Sheet1!$D$3 -> 0.00144 | P28: =J28*O28 -> 0 | Q28: =Sheet1!$D$4 -> 0.00047 | R28: =Q28*J28 -> 0
A29: SPI-20 | C29: 30.885416 | D29: 75.897013 | G29: Punjab | H29: India | I29: Operating | K29: =Sheet1!$D$5 -> 0.00381 | L29: =J29*K29 -> 0 | M29: =Sheet1!$D$2 -> 0.00251 | N29: =J29*M29 -> 0 | O29: =Sheet1!$D$3 -> 0.00144 | P29: =J29*O29 -> 0 | Q29: =Sheet1!$D$4 -> 0.00047 | R29: =Q29*J29 -> 0
A30: SPI-21 | C30: 30.887595 | D30: 75.907098 | G30: Punjab | H30: India | I30: Operating | K30: =Sheet1!$D$5 -> 0.00381 | L30: =J30*K30 -> 0 | M30: =Sheet1!$D$2 -> 0.00251 | N30: =J30*M30 -> 0 | O30: =Sheet1!$D$3 -> 0.00144 | P30: =J30*O30 -> 0 | Q30: =Sheet1!$D$4 -> 0.00047 | R30: =Q30*J30 -> 0
A31: SPI-22 | B31: Essar Steel India Ltd | C31: 21.111323 | D31: 72.643813 | E31: Integrated | G31: Gujarat | H31: India | I31: Operating | K31: =Sheet1!$D$5 -> 0.00381 | L31: =J31*K31 -> 0 | M31: =Sheet1!$D$2 -> 0.00251 | N31: =J31*M31 -> 0 | O31: =Sheet1!$D$3 -> 0.00144 | P31: =J31*O31 -> 0 | Q31: =Sheet1!$D$4 -> 0.00047 | R31: =Q31*J31 -> 0
A32: SPI-23 | B32: Essar Steel India Ltd | C32: 18.655587 | D32: 73.796152 | G32: Maharashtra | H32: India | I32: Operating | K32: =Sheet1!$D$5 -> 0.00381 | L32: =J32*K32 -> 0 | M32: =Sheet1!$D$2 -> 0.00251 | N32: =J32*M32 -> 0 | O32: =Sheet1!$D$3 -> 0.00144 | P32: =J32*O32 -> 0 | Q32: =Sheet1!$D$4 -> 0.00047 | R32: =Q32*J32 -> 0
A33: SPI-24 | B33: Essar Steel India Ltd | C33: 17.719148 | D33: 83.274564 | G33: Andhra Pradesh | H33: India | I33: Operating | K33: =Sheet1!$D$5 -> 0.00381 | L33: =J33*K33 -> 0 | M33: =Sheet1!$D$2 -> 0.00251 | N33: =J33*M33 -> 0 | O33: =Sheet1!$D$3 -> 0.00144 | P33: =J33*O33 -> 0 | Q33: =Sheet1!$D$4 -> 0.00047 | R33: =Q33*J33 -> 0
A34: SPI-25 | B34: Essar Steel India Ltd | C34: 20.321457 | D34: 86.647655 | G34: Odisha | H34: India | I34: Operating | K34: =Sheet1!$D$5 -> 0.00381 | L34: =J34*K34 -> 0 | M34: =Sheet1!$D$2 -> 0.00251 | N34: =J34*M34 -> 0 | O34: =Sheet1!$D$3 -> 0.00144 | P34: =J34*O34 -> 0 | Q34: =Sheet1!$D$4 -> 0.00047 | R34: =Q34*J34 -> 0
A35: SPI-26 | B35: BMM ISPAT Ltd | C35: 15.171144 | D35: 76.377767 | E35: Integrated | G35: Karnataka | H35: India | I35: Operating | K35: =Sheet1!$D$5 -> 0.00381 | L35: =J35*K35 -> 0 | M35: =Sheet1!$D$2 -> 0.00251 | N35: =J35*M35 -> 0 | O35: =Sheet1!$D$3 -> 0.00144 | P35: =J35*O35 -> 0 | Q35: =Sheet1!$D$4 -> 0.00047 | R35: =Q35*J35 -> 0
A36: SPI-27 | B36: JSW Steel Ltd | C36: 18.690094 | D36: 73.037536 | E36: Integrated | G36: Maharashtra | H36: India | I36: Operating | K36: =Sheet1!$D$5 -> 0.00381 | L36: =J36*K36 -> 0 | M36: =Sheet1!$D$2 -> 0.00251 | N36: =J36*M36 -> 0 | O36: =Sheet1!$D$3 -> 0.00144 | P36: =J36*O36 -> 0 | Q36: =Sheet1!$D$4 -> 0.00047 | R36: =Q36*J36 -> 0
A37: SPI-28 | B37: JSW Steel Ltd | C37: 11.81618 | D37: 77.914704 | E37: Integrated | G37: Tamil Nadu | H37: India | I37: Operating | K37: =Sheet1!$D$5 -> 0.00381 | L37: =J37*K37 -> 0 | M37: =Sheet1!$D$2 -> 0.00251 | N37: =J37*M37 -> 0 | O37: =Sheet1!$D$3 -> 0.00144 | P37: =J37*O37 -> 0 | Q37: =Sheet1!$D$4 -> 0.00047 | R37: =Q37*J37 -> 0
A38: SPI-29 | B38: JSW Steel Ltd | C38: 15.18054 | D38: 76.65684 | E38: Integrated | G38: Karnataka | H38: India | I38: Operating | K38: =Sheet1!$D$5 -> 0.00381 | L38: =J38*K38 -> 0 | M38: =Sheet1!$D$2 -> 0.00251 | N38: =J38*M38 -> 0 | O38: =Sheet1!$D$3 -> 0.00144 | P38: =J38*O38 -> 0 | Q38: =Sheet1!$D$4 -> 0.00047 | R38: =Q38*J38 -> 0
A39: SPI-30 | B39: Bhushan Power & Steel Ltd | C39: 21.760298 | D39: 84.022268 | E39: Integrated | G39: Odisha | H39: India | I39: Operating | J39: =1000000*3.5 -> 3500000 | K39: =Sheet1!$D$5 -> 0.00381 | L39: =J39*K39 -> 13335 | M39: =Sheet1!$D$2 -> 0.00251 | N39: =J39*M39 -> 8785 | O39: =Sheet1!$D$3 -> 0.00144 | P39: =J39*O39 -> 5040 | Q39: =Sheet1!$D$4 -> 0.00047 | R39: =Q39*J39 -> 1645
A40: SPI-31 | B40: JSW Ispat Steel Ltd | C40: 21.983709 | D40: 83.238133 | E40: Integrated | G40: Chhattisgarh | H40: India | I40: Operating | J40: =1000000*1.5 -> 1500000 | K40: =Sheet1!$D$5 -> 0.00381 | L40: =J40*K40 -> 5715 | M40: =Sheet1!$D$2 -> 0.00251 | N40: =J40*M40 -> 3765 | O40: =Sheet1!$D$3 -> 0.00144 | P40: =J40*O40 -> 2160 | Q40: =Sheet1!$D$4 -> 0.00047 | R40: =Q40*J40 -> 705
...

Sheet Sheet1
A1: Pollutant | B1: EF | C1: Unit | D1: EF normalised (tonnes of pollutant/tonnes of production) | E1: Notes
A2: PM2.5 | B2: 2.51 | C2: tonne/000 tonnes | D2: =B2/1000 -> 0.00251
A3: SO2 | B3: 1.44 | C3: tonne/000 tonnes | D3: =B3/1000 -> 0.00144
A4: NOx | B4: 0.47 | C4: tonne/000 tonnes | D4: =B4/1000 -> 0.00047
A5: PM10* | B5: 3.81 | C5: tonne/000 tonnes | D5: =B5/1000 -> 0.00381 | E5: This is estimated by taking global PM10:PM2.5 ratio from the paper that is 1.5185 and multiplying that with PM2.5 EF
A8: The average emission intensities of developing countries are 2.51 ton of PM2.5, 1.44 ton of SO2, and 0.47 ton of NOx per thousand ton of crude steel produced.
A10: Source | B10: Zhang, J., Shen, H., Chen, Y., Meng, J., Li, J., He, J., Guo, P., Dai, R., Zhang, Y., Xu, R., Wang, J., Zheng, S., Lei, T., Shen, G., Wang, C., Ye, J., Zhu, L., Sun, H. Z., Fu, T.-M., Yang, X., Guan, D. & Tao, S. (2023) ‘Iron and Steel Industry Emissions: A Global Analysis of Trends and Drivers’, Environmental Science & Technology, 57(43). doi: 10.1021/acs.est.3c05474
