Workbook

Sheet coal_plants_main
A1: id | B1: name | C1: lat | D1: lon | E1: type | F1: fuel | G1: region | H1: country | I1: status | J1: capacities | K1: capacity_power | L1: prod_kw | M1: emfpm10 | N1: pm10_t_yr | O1: emfpm25 | P1: pm25_t_yr | Q1: emfso2 | R1: so2_t_yr | S1: emfnox | T1: nox_t_yr
A2: CB-1 | B2: Barapukuria power station | C2: 25.553757 | D2: 88.948631 | E2: coal plant | F2: coal | G2: Dinajpur | H2: Bangladesh | I2: operating, operating, operating | J2: 125, 125, 275 | K2: {=SUM(VALUE(_xlfn.TEXTSPLIT(J2, ",")))} -> 525 | L2: =(K2*1000*24*365) -> 4599000000 | M2: =Sheet1!$D$5 -> 0.00037 | N2: =((L2*M2)/1000)*0.05 -> 85.0815 | O2: =Sheet1!$D$2 -> 0.00019 | P2: =((L2*O2)/1000)*0.05 -> 43.6905 | Q2: =Sheet1!$D$3 -> 0.0072 | R2: =((L2*Q2)/1000)*0.05 -> 1655.64 | S2: =Sheet1!$D$4 -> 0.0043 | T2: =((S2*L2)/1000)*0.05 -> 988.785
A3: CB-2 | B3: Patuakhali power station (RPCL/NORINCO) | C3: 22.025149 | D3: 90.312349 | E3: coal plant | F3: coal | G3: Patuakhali | H3: Bangladesh | I3: construction, construction | J3: 660, 660 | K3: {=SUM(VALUE(_xlfn.TEXTSPLIT(J3, ",")))} -> 1320 | L3: =(K3*1000*24*365) -> 11563200000 | M3: =Sheet1!$D$5 -> 0.00037 | N3: =((L3*M3)/1000)*0.05 -> 213.9192 | O3: =Sheet1!$D$2 -> 0.00019 | P3: =((L3*O3)/1000)*0.05 -> 109.8504 | Q3: =Sheet1!$D$3 -> 0.0072 | R3: =((L3*Q3)/1000)*0.05 -> 4162.752 | S3: =Sheet1!$D$4 -> 0.0043 | T3: =((S3*L3)/1000)*0.05 -> 2486.088
A4: CB-3 | B4: Payra power station (BCPCL) | C4: 21.999778 | D4: 90.305586 | E4: coal plant | F4: coal | G4: Patuakhali | H4: Bangladesh | I4: operating, operating, construction, construction | J4: 660, 660, 660, 660 | K4: {=SUM(VALUE(_xlfn.TEXTSPLIT(J4, ",")))} -> 2640 | L4: =(K4*1000*24*365) -> 23126400000 | M4: =Sheet1!$D$5 -> 0.00037 | N4: =((L4*M4)/1000)*0.05 -> 427.8384 | O4: =Sheet1!$D$2 -> 0.00019 | P4: =((L4*O4)/1000)*0.05 -> 219.7008 | Q4: =Sheet1!$D$3 -> 0.0072 | R4: =((L4*Q4)/1000)*0.05 -> 8325.504 | S4: =Sheet1!$D$4 -> 0.0043 | T4: =((S4*L4)/1000)*0.05 -> 4972.176
A5: CB-5 | B5: Barisal power station | C5: 21.963 | D5: 90.0655 | E5: coal plant | F5: coal | G5: Barisal | H5: Bangladesh | I5: operating | J5: 350 | K5: {=SUM(VALUE(_xlfn.TEXTSPLIT(J5, ",")))} -> 350 | L5: =(K5*1000*24*365) -> 3066000000 | M5: =Sheet1!$D$5 -> 0.00037 | N5: =((L5*M5)/1000)*0.05 -> 56.721 | O5: =Sheet1!$D$2 -> 0.00019 | P5: =((L5*O5)/1000)*0.05 -> 29.127 | Q5: =Sheet1!$D$3 -> 0.0072 | R5: =((L5*Q5)/1000)*0.05 -> 1103.76 | S5: =Sheet1!$D$4 -> 0.0043 | T5: =((S5*L5)/1000)*0.05 -> 659.19
A6: CB-4 | B6: Rampal power station | C6: 22.592458 | D6: 89.556427 | E6: coal plant | F6: coal | G6: Khulna | H6: Bangladesh | I6: operating, construction | J6: 660, 660 | K6: {=SUM(VALUE(_xlfn.TEXTSPLIT(J6, ",")))} -> 1320 | L6: =(K6*1000*24*365) -> 11563200000 | M6: =Sheet1!$D$5 -> 0.00037 | N6: =((L6*M6)/1000)*0.05 -> 213.9192 | O6: =Sheet1!$D$2 -> 0.00019 | P6: =((L6*O6)/1000)*0.05 -> 109.8504 | Q6: =Sheet1!$D$3 -> 0.0072 | R6: =((L6*Q6)/1000)*0.05 -> 4162.752 | S6: =Sheet1!$D$4 -> 0.0043 | T6: =((S6*L6)/1000)*0.05 -> 2486.088
A7: CI-1 | B7: Adani Godda power station | C7: 24.81411 | D7: 87.13547 | E7: coal plant | F7: coal | G7: Jharkhand | H7: India | I7: operating, operating | J7: 800, 800 | K7: {=SUM(VALUE(_xlfn.TEXTSPLIT(J7, ",")))} -> 1600 | L7: =(K7*1000*24*365) -> 14016000000 | M7: =Sheet1!$D$5 -> 0.00037 | N7: =((L7*M7)/1000)*0.05 -> 259.296 | O7: =Sheet1!$D$2 -> 0.00019 | P7: =((L7*O7)/1000)*0.05 -> 133.152 | Q7: =Sheet1!$D$3 -> 0.0072 | R7: =((L7*Q7)/1000)*0.05 -> 5045.76 | S7: =Sheet1!$D$4 -> 0.0043 | T7: =((S7*L7)/1000)*0.05 -> 3013.44
A8: CI-2 | B8: Angul Smelter power station (Meja Urja Nigam Pvt Ltd) | C8: 25.14587 | D8: 81.9401 | E8: captive power plant | F8: coal | G8: Uttar Pradesh | H8: India | I8: pre-permit | J8: 800 | K8: {=SUM(VALUE(_xlfn.TEXTSPLIT(J8, ",")))} -> 800 | L8: =(K8*1000*24*365) -> 7008000000 | M8: =Sheet1!$D$5 -> 0.00037 | N8: =((L8*M8)/1000)*0.05 -> 129.648 | O8: =Sheet1!$D$2 -> 0.00019 | P8: =((L8*O8)/1000)*0.05 -> 66.576 | Q8: =Sheet1!$D$3 -> 0.0072 | R8: =((L8*Q8)/1000)*0.05 -> 2522.88 | S8: =Sheet1!$D$4 -> 0.0043 | T8: =((S8*L8)/1000)*0.05 -> 1506.72
A9: CI-3 | B9: Angul Smelter power station (Mirzapur Thermal Energy (UP) Pvt Ltd) | C9: 25.13658 | D9: 82.5622 | E9: captive power plant | F9: coal | G9: Uttar Pradesh | H9: India | I9: pre-permit | J9: 800 | K9: {=SUM(VALUE(_xlfn.TEXTSPLIT(J9, ",")))} -> 800 | L9: =(K9*1000*24*365) -> 7008000000 | M9: =Sheet1!$D$5 -> 0.00037 | N9: =((L9*M9)/1000)*0.05 -> 129.648 | O9: =Sheet1!$D$2 -> 0.00019 | P9: =((L9*O9)/1000)*0.05 -> 66.576 | Q9: =Sheet1!$D$3 -> 0.0072 | R9: =((L9*Q9)/1000)*0.05 -> 2522.88 | S9: =Sheet1!$D$4 -> 0.0043 | T9: =((S9*L9)/1000)*0.05 -> 1506.72
A10: CI-4 | B10: Anpara power station | C10: 24.20204 | D10: 82.78913 | E10: coal plant | F10: coal | G10: Uttar Pradesh | H10: India | I10: operating, operating, operating, operating, operating | J10: 210, 210, 210, 500, 500 | K10: {=SUM(VALUE(_xlfn.TEXTSPLIT(J10, ",")))} -> 1630 | L10: =(K10*1000*24*365) -> 14278800000 | M10: =Sheet1!$D$5 -> 0.00037 | N10: =((L10*M10)/1000)*0.05 -> 264.1578 | O10: =Sheet1!$D$2 -> 0.00019 | P10: =((L10*O10)/1000)*0.05 -> 135.6486 | Q10: =Sheet1!$D$3 -> 0.0072 | R10: =((L10*Q10)/1000)*0.05 -> 5140.368 | S10: =Sheet1!$D$4 -> 0.0043 | T10: =((S10*L10)/1000)*0.05 -> 3069.942
A11: CI-5 | B11: Anpara-C power station | C11: 24.20379 | D11: 82.79733 | E11: coal plant | F11: coal | G11: Uttar Pradesh | H11: India | I11: operating, operating | J11: 600, 600 | K11: {=SUM(VALUE(_xlfn.TEXTSPLIT(J11, ",")))} -> 1200 | L11: =(K11*1000*24*365) -> 10512000000 | M11: =Sheet1!$D$5 -> 0.00037 | N11: =((L11*M11)/1000)*0.05 -> 194.472 | O11: =Sheet1!$D$2 -> 0.00019 | P11: =((L11*O11)/1000)*0.05 -> 99.864 | Q11: =Sheet1!$D$3 -> 0.0072 | R11: =((L11*Q11)/1000)*0.05 -> 3784.32 | S11: =Sheet1!$D$4 -> 0.0043 | T11: =((S11*L11)/1000)*0.05 -> 2260.08
A12: CI-6 | B12: Anpara-D power station | C12: 24.19626 | D12: 82.80634 | E12: coal plant | F12: coal | G12: Uttar Pradesh | H12: India | I12: operating, operating | J12: 500, 500 | K12: {=SUM(VALUE(_xlfn.TEXTSPLIT(J12, ",")))} -> 1000 | L12: =(K12*1000*24*365) -> 8760000000 | M12: =Sheet1!$D$5 -> 0.00037 | N12: =((L12*M12)/1000)*0.05 -> 162.06 | O12: =Sheet1!$D$2 -> 0.00019 | P12: =((L12*O12)/1000)*0.05 -> 83.22 | Q12: =Sheet1!$D$3 -> 0.0072 | R12: =((L12*Q12)/1000)*0.05 -> 3153.6 | S12: =Sheet1!$D$4 -> 0.0043 | T12: =((S12*L12)/1000)*0.05 -> 1883.4
A13: CI-7 | B13: Anpara-E power station | C13: 26.19278 | D13: 79.94028 | E13: coal plant | F13: coal | G13: Uttar Pradesh | H13: India | I13: permitted, permitted | J13: 660, 660 | K13: {=SUM(VALUE(_xlfn.TEXTSPLIT(J13, ",")))} -> 1320 | L13: =(K13*1000*24*365) -> 11563200000 | M13: =Sheet1!$D$5 -> 0.00037 | N13: =((L13*M13)/1000)*0.05 -> 213.9192 | O13: =Sheet1!$D$2 -> 0.00019 | P13: =((L13*O13)/1000)*0.05 -> 109.8504 | Q13: =Sheet1!$D$3 -> 0.0072 | R13: =((L13*Q13)/1000)*0.05 -> 4162.752 | S13: =Sheet1!$D$4 -> 0.0043 | T13: =((S13*L13)/1000)*0.05 -> 2486.088
A14: CI-8 | B14: Asansol Crescent power station | C14: 23.78457 | D14: 87.047245 | E14: coal plant | F14: coal | G14: West Bengal | H14: India | I14: operating | J14: 40 | K14: {=SUM(VALUE(_xlfn.TEXTSPLIT(J14, ",")))} -> 40 | L14: =(K14*1000*24*365) -> 350400000 | M14: =Sheet1!$D$5 -> 0.00037 | N14: =((L14*M14)/1000)*0.05 -> 6.4824 | O14: =Sheet1!$D$2 -> 0.00019 | P14: =((L14*O14)/1000)*0.05 -> 3.3288 | Q14: =Sheet1!$D$3 -> 0.0072 | R14: =((L14*Q14)/1000)*0.05 -> 126.144 | S14: =Sheet1!$D$4 -> 0.0043 | T14: =((S14*L14)/1000)*0.05 -> 75.336
A15: CI-9 | B15: Badarpur Thermal Power Station Stage I | C15: 22.995746 | D15: 88.403815 | E15: coal plant | F15: coal | G15: West Bengal | H15: India | I15: operating, operating, operating | J15: 95, 95, 95 | K15: {=SUM(VALUE(_xlfn.TEXTSPLIT(J15, ",")))} -> 285 | L15: =(K15*1000*24*365) -> 2496600000 | M15: =Sheet1!$D$5 -> 0.00037 | N15: =((L15*M15)/1000)*0.05 -> 46.1871 | O15: =Sheet1!$D$2 -> 0.00019 | P15: =((L15*O15)/1000)*0.05 -> 23.7177 | Q15: =Sheet1!$D$3 -> 0.0072 | R15: =((L15*Q15)/1000)*0.05 -> 898.776 | S15: =Sheet1!$D$4 -> 0.0043 | T15: =((S15*L15)/1000)*0.05 -> 536.769
A16: CI-10 | B16: Badarpur Thermal Power Station Stage II | C16: 24.714 | D16: 86.9583 | E16: coal plant | F16: coal | G16: Bihar | H16: India | I16: operating, operating | J16: 210, 210 | K16: {=SUM(VALUE(_xlfn.TEXTSPLIT(J16, ",")))} -> 420 | L16: =(K16*1000*24*365) -> 3679200000 | M16: =Sheet1!$D$5 -> 0.00037 | N16: =((L16*M16)/1000)*0.05 -> 68.0652 | O16: =Sheet1!$D$2 -> 0.00019 | P16: =((L16*O16)/1000)*0.05 -> 34.9524 | Q16: =Sheet1!$D$3 -> 0.0072 | R16: =((L16*Q16)/1000)*0.05 -> 1324.512 | S16: =Sheet1!$D$4 -> 0.0043 | T16: =((S16*L16)/1000)*0.05 -> 791.028
A17: CI-11 | B17: Bakreswar Thermal Power Station Phase I | C17: 25.391376 | D17: 86.023488 | E17: coal plant | F17: coal | G17: Bihar | H17: India | I17: operating, operating, operating | J17: 210, 210, 210 | K17: {=SUM(VALUE(_xlfn.TEXTSPLIT(J17, ",")))} -> 630 | L17: =(K17*1000*24*365) -> 5518800000 | M17: =Sheet1!$D$5 -> 0.00037 | N17: =((L17*M17)/1000)*0.05 -> 102.0978 | O17: =Sheet1!$D$2 -> 0.00019 | P17: =((L17*O17)/1000)*0.05 -> 52.4286 | Q17: =Sheet1!$D$3 -> 0.0072 | R17: =((L17*Q17)/1000)*0.05 -> 1986.768 | S17: =Sheet1!$D$4 -> 0.0043 | T17: =((S17*L17)/1000)*0.05 -> 1186.542
A18: CI-12 | B18: Bakreswar Thermal Power Station Phase II | C18: 23.829221 | D18: 87.451034 | E18: coal plant | F18: coal | G18: West Bengal | H18: India | I18: operating, operating | J18: 210, 210 | K18: {=SUM(VALUE(_xlfn.TEXTSPLIT(J18, ",")))} -> 420 | L18: =(K18*1000*24*365) -> 3679200000 | M18: =Sheet1!$D$5 -> 0.00037 | N18: =((L18*M18)/1000)*0.05 -> 68.0652 | O18: =Sheet1!$D$2 -> 0.00019 | P18: =((L18*O18)/1000)*0.05 -> 34.9524 | Q18: =Sheet1!$D$3 -> 0.0072 | R18: =((L18*Q18)/1000)*0.05 -> 1324.512 | S18: =Sheet1!$D$4 -> 0.0043 | T18: =((S18*L18)/1000)*0.05 -> 791.028
A19: CI-13 | B19: Bandel Thermal Power Station | C19: 22.99575 | D19: 88.40382 | E19: coal plant | F19: coal | G19: West Bengal | H19: India | I19: operating, operating, operating, operating, operating | J19: 60, 210, 60, 60, 60 | K19: {=SUM(VALUE(_xlfn.TEXTSPLIT(J19, ",")))} -> 450 | L19: =(K19*1000*24*365) -> 3942000000 | M19: =Sheet1!$D$5 -> 0.00037 | N19: =((L19*M19)/1000)*0.05 -> 72.927 | O19: =Sheet1!$D$2 -> 0.00019 | P19: =((L19*O19)/1000)*0.05 -> 37.449 | Q19: =Sheet1!$D$3 -> 0.0072 | R19: =((L19*Q19)/1000)*0.05 -> 1419.12 | S19: =Sheet1!$D$4 -> 0.0043 | T19: =((S19*L19)/1000)*0.05 -> 847.53
A20: CI-14 | B20: Bara Thermal Power Project | C20: 25.19635 | D20: 81.65853 | E20: coal plant | F20: coal | G20: Uttar Pradesh | H20: India | I20: operating, operating, operating | J20: 660, 660, 660 | K20: {=SUM(VALUE(_xlfn.TEXTSPLIT(J20, ",")))} -> 1980 | L20: =(K20*1000*24*365) -> 17344800000 | M20: =Sheet1!$D$5 -> 0.00037 | N20: =((L20*M20)/1000)*0.05 -> 320.8788 | O20: =Sheet1!$D$2 -> 0.00019 | P20: =((L20*O20)/1000)*0.05 -> 164.7756 | Q20: =Sheet1!$D$3 -> 0.0072 | R20: =((L20*Q20)/1000)*0.05 -> 6244.128 | S20: =Sheet1!$D$4 -> 0.0043 | T20: =((S20*L20)/1000)*0.05 -> 3729.132
A21: CI-15 | B21: Barauni power station | C21: 25.39138 | D21: 86.02349 | E21: coal plant | F21: coal | G21: Bihar | H21: India | I21: operating, operating, operating, operating | J21: 250, 250, 110, 110 | K21: {=SUM(VALUE(_xlfn.TEXTSPLIT(J21, ",")))} -> 720 | L21: =(K21*1000*24*365) -> 6307200000 | M21: =Sheet1!$D$5 -> 0.00037 | N21: =((L21*M21)/1000)*0.05 -> 116.6832 | O21: =Sheet1!$D$2 -> 0.00019 | P21: =((L21*O21)/1000)*0.05 -> 59.9184 | Q21: =Sheet1!$D$3 -> 0.0072 | R21: =((L21*Q21)/1000)*0.05 -> 2270.592 | S21: =Sheet1!$D$4 -> 0.0043 | T21: =((S21*L21)/1000)*0.05 -> 1356.048
A22: CI-16 | B22: Barh I power station | C22: 25.4693 | D22: 85.74516 | E22: coal plant | F22: coal | G22: Bihar | H22: India | I22: operating, construction, construction | J22: 660, 660, 660 | K22: {=SUM(VALUE(_xlfn.TEXTSPLIT(J22, ",")))} -> 1980 | L22: =(K22*1000*24*365) -> 17344800000 | M22: =Sheet1!$D$5 -> 0.00037 | N22: =((L22*M22)/1000)*0.05 -> 320.8788 | O22: =Sheet1!$D$2 -> 0.00019 | P22: =((L22*O22)/1000)*0.05 -> 164.7756 | Q22: =Sheet1!$D$3 -> 0.0072 | R22: =((L22*Q22)/1000)*0.05 -> 6244.128 | S22: =Sheet1!$D$4 -> 0.0043 | T22: =((S22*L22)/1000)*0.05 -> 3729.132
A23: CI-17 | B23: Barh II power station | C23: 25.4865 | D23: 85.74516 | E23: coal plant | F23: coal | G23: Bihar | H23: India | I23: operating, operating | J23: 660, 660 | K23: {=SUM(VALUE(_xlfn.TEXTSPLIT(J23, ",")))} -> 1320 | L23: =(K23*1000*24*365) -> 11563200000 | M23: =Sheet1!$D$5 -> 0.00037 | N23: =((L23*M23)/1000)*0.05 -> 213.9192 | O23: =Sheet1!$D$2 -> 0.00019 | P23: =((L23*O23)/1000)*0.05 -> 109.8504 | Q23: =Sheet1!$D$3 -> 0.0072 | R23: =((L23*Q23)/1000)*0.05 -> 4162.752 | S23: =Sheet1!$D$4 -> 0.0043 | T23: =((S23*L23)/1000)*0.05 -> 2486.088
A24: CI-18 | B24: Barkhera IPP power station | C24: 28.4722 | D24: 79.806725 | E24: coal plant | F24: coal | G24: Uttar Pradesh | H24: India | I24: operating, operating | J24: 45, 45 | K24: {=SUM(VALUE(_xlfn.TEXTSPLIT(J24, ",")))} -> 90 | L24: =(K24*1000*24*365) -> 788400000 | M24: =Sheet1!$D$5 -> 0.00037 | N24: =((L24*M24)/1000)*0.05 -> 14.5854 | O24: =Sheet1!$D$2 -> 0.00019 | P24: =((L24*O24)/1000)*0.05 -> 7.4898 | Q24: =Sheet1!$D$3 -> 0.0072 | R24: =((L24*Q24)/1000)*0.05 -> 283.824 | S24: =Sheet1!$D$4 -> 0.0043 | T24: =((S24*L24)/1000)*0.05 -> 169.506
A25: CI-19 | B25: Bilhaur Super Thermal Power Plant | C25: 26.76339 | D25: 80.05806 | E25: coal plant | F25: coal | G25: Uttar Pradesh | H25: India | I25: pre-permit, pre-permit | J25: 660, 660 | K25: {=SUM(VALUE(_xlfn.TEXTSPLIT(J25, ",")))} -> 1320 | L25: =(K25*1000*24*365) -> 11563200000 | M25: =Sheet1!$D$5 -> 0.00037 | N25: =((L25*M25)/1000)*0.05 -> 213.9192 | O25: =Sheet1!$D$2 -> 0.00019 | P25: =((L25*O25)/1000)*0.05 -> 109.8504 | Q25: =Sheet1!$D$3 -> 0.0072 | R25: =((L25*Q25)/1000)*0.05 -> 4162.752 | S25: =Sheet1!$D$4 -> 0.0043 | T25: =((S25*L25)/1000)*0.05 -> 2486.088
A26: CI-20 | B26: Budge Budge Generating Station | C26: 22.47034 | D26: 88.13995 | E26: coal plant | F26: coal | G26: West Bengal | H26: India | I26: operating, operating, operating | J26: 250, 250, 250 | K26: {=SUM(VALUE(_xlfn.TEXTSPLIT(J26, ",")))} -> 750 | L26: =(K26*1000*24*365) -> 6570000000 | M26: =Sheet1!$D$5 -> 0.00037 | N26: =((L26*M26)/1000)*0.05 -> 121.545 | O26: =Sheet1!$D$2 -> 0.00019 | P26: =((L26*O26)/1000)*0.05 -> 62.415 | Q26: =Sheet1!$D$3 -> 0.0072 | R26: =((L26*Q26)/1000)*0.05 -> 2365.2 | S26: =Sheet1!$D$4 -> 0.0043 | T26: =((S26*L26)/1000)*0.05 -> 1412.55
A27: CI-21 | B27: Chandrapur Thermal Power Station (Bihar State Power Holding Co Ltd) | C27: 25.39138 | D27: 86.02349 | E27: coal plant | F27: coal | G27: Bihar | H27: India | I27: operating | J27: 250 | K27: {=SUM(VALUE(_xlfn.TEXTSPLIT(J27, ",")))} -> 250 | L27: =(K27*1000*24*365) -> 2190000000 | M27: =Sheet1!$D$5 -> 0.00037 | N27: =((L27*M27)/1000)*0.05 -> 40.515 | O27: =Sheet1!$D$2 -> 0.00019 | P27: =((L27*O27)/1000)*0.05 -> 20.805 | Q27: =Sheet1!$D$3 -> 0.0072 | R27: =((L27*Q27)/1000)*0.05 -> 788.4 | S27: =Sheet1!$D$4 -> 0.0043 | T27: =((S27*L27)/1000)*0.05 -> 470.85
A28: CI-22 | B28: Buxar Thermal Power Station | C28: 25.46235 | D28: 83.88257 | E28: coal plant | F28: coal | G28: Bihar | H28: India | I28: construction, construction | J28: 660, 660 | K28: {=SUM(VALUE(_xlfn.TEXTSPLIT(J28, ",")))} -> 1320 | L28: =(K28*1000*24*365) -> 11563200000 | M28: =Sheet1!$D$5 -> 0.00037 | N28: =((L28*M28)/1000)*0.05 -> 213.9192 | O28: =Sheet1!$D$2 -> 0.00019 | P28: =((L28*O28)/1000)*0.05 -> 109.8504 | Q28: =Sheet1!$D$3 -> 0.0072 | R28: =((L28*Q28)/1000)*0.05 -> 4162.752 | S28: =Sheet1!$D$4 -> 0.0043 | T28: =((S28*L28)/1000)*0.05 -> 2486.088
A29: CI-23 | B29: Chunar Cement power station | C29: 25.09089 | D29: 82.89734 | E29: captive power plant | F29: coal | G29: Uttar Pradesh | H29: India | I29: operating | J29: 38 | K29: {=SUM(VALUE(_xlfn.TEXTSPLIT(J29, ",")))} -> 38 | L29: =(K29*1000*24*365) -> 332880000 | M29: =Sheet1!$D$5 -> 0.00037 | N29: =((L29*M29)/1000)*0.05 -> 6.15828 | O29: =Sheet1!$D$2 -> 0.00019 | P29: =((L29*O29)/1000)*0.05 -> 3.16236 | Q29: =Sheet1!$D$3 -> 0.0072 | R29: =((L29*Q29)/1000)*0.05 -> 119.8368 | S29: =Sheet1!$D$4 -> 0.0043 | T29: =((S29*L29)/1000)*0.05 -> 71.5692
A30: CI-24 | B30: Churk captive power station | C30: 24.6391 | D30: 83.10109 | E30: captive power plant | F30: coal | G30: Uttar Pradesh | H30: India | I30: operating, operating, operating, operating | J30: 60, 60, 60, 60 | K30: {=SUM(VALUE(_xlfn.TEXTSPLIT(J30, ",")))} -> 240 | L30: =(K30*1000*24*365) -> 2102400000 | M30: =Sheet1!$D$5 -> 0.00037 | N30: =((L30*M30)/1000)*0.05 -> 38.8944 | O30: =Sheet1!$D$2 -> 0.00019 | P30: =((L30*O30)/1000)*0.05 -> 19.9728 | Q30: =Sheet1!$D$3 -> 0.0072 | R30: =((L30*Q30)/1000)*0.05 -> 756.864 | S30: =Sheet1!$D$4 -> 0.0043 | T30: =((S30*L30)/1000)*0.05 -> 452.016
A31: CI-25 | B31: Deenbandhu Chhotu Ram Thermal Power Plant | C31: 30.10541 | D31: 77.32697 | E31: coal plant | F31: coal | G31: Haryana | H31: India | I31: operating, operating | J31: 300, 300 | K31: {=SUM(VALUE(_xlfn.TEXTSPLIT(J31, ",")))} -> 600 | L31: =(K31*1000*24*365) -> 5256000000 | M31: =Sheet1!$D$5 -> 0.00037 | N31: =((L31*M31)/1000)*0.05 -> 97.236 | O31: =Sheet1!$D$2 -> 0.00019 | P31: =((L31*O31)/1000)*0.05 -> 49.932 | Q31: =Sheet1!$D$3 -> 0.0072 | R31: =((L31*Q31)/1000)*0.05 -> 1892.16 | S31: =Sheet1!$D$4 -> 0.0043 | T31: =((S31*L31)/1000)*0.05 -> 1130.04
A32: CI-26 | B32: Durgapur SAIL power station | C32: 23.55181 | D32: 87.24848 | E32: captive power plant | F32: coal | G32: West Bengal | H32: India | I32: operating, operating | J32: 60, 60 | K32: {=SUM(VALUE(_xlfn.TEXTSPLIT(J32, ",")))} -> 120 | L32: =(K32*1000*24*365) -> 1051200000 | M32: =Sheet1!$D$5 -> 0.00037 | N32: =((L32*M32)/1000)*0.05 -> 19.4472 | O32: =Sheet1!$D$2 -> 0.00019 | P32: =((L32*O32)/1000)*0.05 -> 9.9864 | Q32: =Sheet1!$D$3 -> 0.0072 | R32: =((L32*Q32)/1000)*0.05 -> 378.432 | S32: =Sheet1!$D$4 -> 0.0043 | T32: =((S32*L32)/1000)*0.05 -> 226.008
A33: CI-27 | B33: Durgapur Steel City Andal power station | C33: 23.58 | D33: 87.2043 | E33: captive power plant | F33: coal | G33: West Bengal | H33: India | I33: operating, operating | J33: 500, 500 | K33: {=SUM(VALUE(_xlfn.TEXTSPLIT(J33, ",")))} -> 1000 | L33: =(K33*1000*24*365) -> 8760000000 | M33: =Sheet1!$D$5 -> 0.00037 | N33: =((L33*M33)/1000)*0.05 -> 162.06 | O33: =Sheet1!$D$2 -> 0.00019 | P33: =((L33*O33)/1000)*0.05 -> 83.22 | Q33: =Sheet1!$D$3 -> 0.0072 | R33: =((L33*Q33)/1000)*0.05 -> 3153.6 | S33: =Sheet1!$D$4 -> 0.0043 | T33: =((S33*L33)/1000)*0.05 -> 1883.4
A34: CI-28 | B34: Farakka power station | C34: 24.77273 | D34: 87.89371 | E34: coal plant | F34: coal | G34: West Bengal | H34: India | I34: operating, operating, operating, operating, operating, operating | J34: 200, 200, 200, 500, 500, 500 | K34: {=SUM(VALUE(_xlfn.TEXTSPLIT(J34, ",")))} -> 2100 | L34: =(K34*1000*24*365) -> 18396000000 | M34: =Sheet1!$D$5 -> 0.00037 | N34: =((L34*M34)/1000)*0.05 -> 340.326 | O34: =Sheet1!$D$2 -> 0.00019 | P34: =((L34*O34)/1000)*0.05 -> 174.762 | Q34: =Sheet1!$D$3 -> 0.0072 | R34: =((L34*Q34)/1000)*0.05 -> 6622.56 | S34: =Sheet1!$D$4 -> 0.0043 | T34: =((S34*L34)/1000)*0.05 -> 3955.14
A35: CI-29 | B35: Feroze Gandhi Unchahar Power Station | C35: 25.91376 | D35: 81.32724 | E35: coal plant | F35: coal | G35: Uttar Pradesh | H35: India | I35: operating, operating, operating, operating, operating, operating | J35: 210, 210, 210, 210, 210, 500 | K35: {=SUM(VALUE(_xlfn.TEXTSPLIT(J35, ",")))} -> 1550 | L35: =(K35*1000*24*365) -> 13578000000 | M35: =Sheet1!$D$5 -> 0.00037 | N35: =((L35*M35)/1000)*0.05 -> 251.193 | O35: =Sheet1!$D$2 -> 0.00019 | P35: =((L35*O35)/1000)*0.05 -> 128.991 | Q35: =Sheet1!$D$3 -> 0.0072 | R35: =((L35*Q35)/1000)*0.05 -> 4888.08 | S35: =Sheet1!$D$4 -> 0.0043 | T35: =((S35*L35)/1000)*0.05 -> 2919.27
A36: CI-30 | B36: Ghatampur power station | C36: 25.975 | D36: 80.1889 | E36: coal plant | F36: coal | G36: Uttar Pradesh | H36: India | I36: construction, construction, construction | J36: 660, 660, 660 | K36: {=SUM(VALUE(_xlfn.TEXTSPLIT(J36, ",")))} -> 1980 | L36: =(K36*1000*24*365) -> 17344800000 | M36: =Sheet1!$D$5 -> 0.00037 | N36: =((L36*M36)/1000)*0.05 -> 320.8788 | O36: =Sheet1!$D$2 -> 0.00019 | P36: =((L36*O36)/1000)*0.05 -> 164.7756 | Q36: =Sheet1!$D$3 -> 0.0072 | R36: =((L36*Q36)/1000)*0.05 -> 6244.128 | S36: =Sheet1!$D$4 -> 0.0043 | T36: =((S36*L36)/1000)*0.05 -> 3729.132
A37: CI-31 | B37: Guru Hargobind Lehra Mohabbat Power Station | C37: 30.26656 | D37: 75.1661 | E37: coal plant | F37: coal | G37: Punjab | H37: India | I37: operating, operating, operating, operating | J37: 210, 210, 250, 250 | K37: {=SUM(VALUE(_xlfn.TEXTSPLIT(J37, ",")))} -> 920 | L37: =(K37*1000*24*365) -> 8059200000 | M37: =Sheet1!$D$5 -> 0.00037 | N37: =((L37*M37)/1000)*0.05 -> 149.0952 | O37: =Sheet1!$D$2 -> 0.00019 | P37: =((L37*O37)/1000)*0.05 -> 76.5624 | Q37: =Sheet1!$D$3 -> 0.0072 | R37: =((L37*Q37)/1000)*0.05 -> 2901.312 | S37: =Sheet1!$D$4 -> 0.0043 | T37: =((S37*L37)/1000)*0.05 -> 1732.728
A38: CI-32 | B38: Guru Nanak Dev Thermal Power Station (GNDTP) Stage I | C38: 28.485091 | D38: 76.37316 | E38: coal plant | F38: coal | G38: Haryana | H38: India | I38: operating, operating, operating, operating | J38: 110, 110, 110, 120 | K38: {=SUM(VALUE(_xlfn.TEXTSPLIT(J38, ",")))} -> 450 | L38: =(K38*1000*24*365) -> 3942000000 | M38: =Sheet1!$D$5 -> 0.00037 | N38: =((L38*M38)/1000)*0.05 -> 72.927 | O38: =Sheet1!$D$2 -> 0.00019 | P38: =((L38*O38)/1000)*0.05 -> 37.449 | Q38: =Sheet1!$D$3 -> 0.0072 | R38: =((L38*Q38)/1000)*0.05 -> 1419.12 | S38: =Sheet1!$D$4 -> 0.0043 | T38: =((S38*L38)/1000)*0.05 -> 847.53
A39: CI-33 | B39: Haldia Energy power station | C39: 22.06046 | D39: 88.10975 | E39: coal plant | F39: coal | G39: West Bengal | H39: India | I39: operating, operating | J39: 600, 600 | K39: {=SUM(VALUE(_xlfn.TEXTSPLIT(J39, ",")))} -> 1200 | L39: =(K39*1000*24*365) -> 10512000000 | M39: =Sheet1!$D$5 -> 0.00037 | N39: =((L39*M39)/1000)*0.05 -> 194.472 | O39: =Sheet1!$D$2 -> 0.00019 | P39: =((L39*O39)/1000)*0.05 -> 99.864 | Q39: =Sheet1!$D$3 -> 0.0072 | R39: =((L39*Q39)/1000)*0.05 -> 3784.32 | S39: =Sheet1!$D$4 -> 0.0043 | T39: =((S39*L39)/1000)*0.05 -> 2260.08
A40: CI-34 | B40: Haldia India Power | C40: 25.236903 | D40: 87.265595 | E40: captive power plant | F40: coal | G40: Bihar | H40: India | I40: construction, construction, construction | J40: 150, 150, 150 | K40: {=SUM(VALUE(_xlfn.TEXTSPLIT(J40, ",")))} -> 450 | L40: =(K40*1000*24*365) -> 3942000000 | M40: =Sheet1!$D$5 -> 0.00037 | N40: =((L40*M40)/1000)*0.05 -> 72.927 | O40: =Sheet1!$D$2 -> 0.00019 | P40: =((L40*O40)/1000)*0.05 -> 37.449 | Q40: =Sheet1!$D$3 -> 0.0072 | R40: =((L40*Q40)/1000)*0.05 -> 1419.12 | S40: =Sheet1!$D$4 -> 0.0043 | T40: =((S40*L40)/1000)*0.05 -> 847.53
...

Sheet Sheet1
A1: Pollutant | B1: EF | C1: Unit | D1: EF normalised (tonnes of pollutant/tonnes of production) | E1: Notes
A2: PM2.5 | B2: 0.19 | C2: tonne/000 tonnes | D2: =B2/1000 -> 0.00019 | E2: Averaged from a range = 0.16-0.22
A3: SO2 | B3: 7.2 | C3: tonne/000 tonnes | D3: =B3/1000 -> 0.0072
A4: NOx | B4: 4.3 | C4: tonne/000 tonnes | D4: =B4/1000 -> 0.0043 | E4: Averaged from a range = 4.22 - 4.38
A5: PM10 | B5: =AVERAGE(0.29,0.45) -> 0.37 | C5: tonne/000 tonnes | D5: =B5/1000 -> 0.00037 | E5: Averaged from a range = 0.29-0.45
A10: Source | B10: India Air Quality - Coal Power Plants Emissions - reference for PM2.5 and PM10 | C10: https://www.indiaairquality.info/wp-content/uploads/docs/2014-08-AE-Emissions-Health-Coal-PPs-India.pdf
B11: US EPA - Emissions Inventory Conference - Reference for So2 and Nox
