Workbook

Sheet paper_pulp_main
A1: id | B1: name | C1: lat | D1: lon | E1: type | F1: fuel | G1: region | H1: country | I1: status | J1: capacity_tonnes | K1: emfpm10 | L1: pm10_t_yr | M1: emfpm25 | N1: pm25_t_yr | O1: emfso2 | P1: so2_t_yr | Q1: emfnox | R1: nox_t_yr
A2: PPB-1 | B2: Amber Super Paper Ltd | C2: 23.807881 | D2: 90.545482 | E2: Paper | G2: Dhaka | H2: Bangladesh | I2: Operating | J2: 16093.74 | K2: =IF(E2="Paper",Sheet1!$E$9,Sheet1!$E$5) -> 0.000189 | L2: =J2*K2 -> 3.0417169 | M2: =IF(E2="Paper",Sheet1!$E$6,Sheet1!$E$2) -> 0.00012285 | N2: =M2*J2 -> 1.977116 | O2: =IF(E2="Paper",Sheet1!$E$7,Sheet1!$E$3) -> 0.00043 | P2: =O2*J2 -> 6.9203082 | Q2: =IF(E2="Paper",Sheet1!$E$8,Sheet1!$E$4) -> 0.00053 | R2: =Q2*J2 -> 8.5296822
A3: PPB-2 | B3: Asia Paper and Board Mills Ltd | C3: 23.579034 | D3: 90.512131 | E3: Paper | G3: Dhaka | H3: Bangladesh | I3: Operating | J3: 16093.74 | K3: =IF(E3="Paper",Sheet1!$E$9,Sheet1!$E$5) -> 0.000189 | L3: =J3*K3 -> 3.0417169 | M3: =IF(E3="Paper",Sheet1!$E$6,Sheet1!$E$2) -> 0.00012285 | N3: =M3*J3 -> 1.977116 | O3: =IF(E3="Paper",Sheet1!$E$7,Sheet1!$E$3) -> 0.00043 | P3: =O3*J3 -> 6.9203082 | Q3: =IF(E3="Paper",Sheet1!$E$8,Sheet1!$E$4) -> 0.00053 | R3: =Q3*J3 -> 8.5296822
A4: PPB-3 | B4: Bangladesh Paper Mills Ltd | C4: 23.70363 | D4: 90.513732 | E4: Paper | G4: Dhaka | H4: Bangladesh | I4: Operating | J4: 16093.74 | K4: =IF(E4="Paper",Sheet1!$E$9,Sheet1!$E$5) -> 0.000189 | L4: =J4*K4 -> 3.0417169 | M4: =IF(E4="Paper",Sheet1!$E$6,Sheet1!$E$2) -> 0.00012285 | N4: =M4*J4 -> 1.977116 | O4: =IF(E4="Paper",Sheet1!$E$7,Sheet1!$E$3) -> 0.00043 | P4: =O4*J4 -> 6.9203082 | Q4: =IF(E4="Paper",Sheet1!$E$8,Sheet1!$E$4) -> 0.00053 | R4: =Q4*J4 -> 8.5296822
A5: PPB-4 | B5: BCIC Bangladesh Chemical Industries Corp. | C5: 23.726751 | D5: 90.419176 | E5: Paper | G5: Dhaka | H5: Bangladesh | I5: Operating | J5: 33069.33 | K5: =IF(E5="Paper",Sheet1!$E$9,Sheet1!$E$5) -> 0.000189 | L5: =J5*K5 -> 6.2501034 | M5: =IF(E5="Paper",Sheet1!$E$6,Sheet1!$E$2) -> 0.00012285 | N5: =M5*J5 -> 4.0625672 | O5: =IF(E5="Paper",Sheet1!$E$7,Sheet1!$E$3) -> 0.00043 | P5: =O5*J5 -> 14.219812 | Q5: =IF(E5="Paper",Sheet1!$E$8,Sheet1!$E$4) -> 0.00053 | R5: =Q5*J5 -> 17.526745
A6: PPB-5 | B6: BPML Bashundhara Paper Mill Limited- Unit 1 | C6: 23.618454 | D6: 90.610732 | E6: pulp and paper | G6: Dhaka | H6: Bangladesh | I6: Operating | J6: 193455.63 | K6: =IF(E6="Paper",Sheet1!$E$9,Sheet1!$E$5) -> 0.0013 | L6: =J6*K6 -> 251.49232 | M6: =IF(E6="Paper",Sheet1!$E$6,Sheet1!$E$2) -> 0.000975 | N6: =M6*J6 -> 188.61924 | O6: =IF(E6="Paper",Sheet1!$E$7,Sheet1!$E$3) -> 0.005 | P6: =O6*J6 -> 967.27815 | Q6: =IF(E6="Paper",Sheet1!$E$8,Sheet1!$E$4) -> 0.0025 | R6: =Q6*J6 -> 483.63908
A7: PPB-6 | B7: BPML Bashundhara Paper Mill Limited- Unit 2 | C7: 23.614185 | D7: 90.61936 | E7: pulp and paper | G7: Dhaka | H7: Bangladesh | I7: Operating | J7: 193455.63 | K7: =IF(E7="Paper",Sheet1!$E$9,Sheet1!$E$5) -> 0.0013 | L7: =J7*K7 -> 251.49232 | M7: =IF(E7="Paper",Sheet1!$E$6,Sheet1!$E$2) -> 0.000975 | N7: =M7*J7 -> 188.61924 | O7: =IF(E7="Paper",Sheet1!$E$7,Sheet1!$E$3) -> 0.005 | P7: =O7*J7 -> 967.27815 | Q7: =IF(E7="Paper",Sheet1!$E$8,Sheet1!$E$4) -> 0.0025 | R7: =Q7*J7 -> 483.63908
A8: PPB-7 | B8: BPML Bashundhara Paper Mill Limited- Unit 3 | C8: 23.575842 | D8: 90.644223 | E8: pulp and paper | G8: Dhaka | H8: Bangladesh | I8: Operating | J8: 193455.63 | K8: =IF(E8="Paper",Sheet1!$E$9,Sheet1!$E$5) -> 0.0013 | L8: =J8*K8 -> 251.49232 | M8: =IF(E8="Paper",Sheet1!$E$6,Sheet1!$E$2) -> 0.000975 | N8: =M8*J8 -> 188.61924 | O8: =IF(E8="Paper",Sheet1!$E$7,Sheet1!$E$3) -> 0.005 | P8: =O8*J8 -> 967.27815 | Q8: =IF(E8="Paper",Sheet1!$E$8,Sheet1!$E$4) -> 0.0025 | R8: =Q8*J8 -> 483.63908
A9: PPB-8 | B9: Hashem Paper Mills Ltd, Zeysha Group | C9: 23.803631 | D9: 90.536589 | E9: Paper | G9: Dhaka | H9: Bangladesh | I9: Operating | J9: 0 | K9: =IF(E9="Paper",Sheet1!$E$9,Sheet1!$E$5) -> 0.000189 | L9: =J9*K9 -> 0 | M9: =IF(E9="Paper",Sheet1!$E$6,Sheet1!$E$2) -> 0.00012285 | N9: =M9*J9 -> 0 | O9: =IF(E9="Paper",Sheet1!$E$7,Sheet1!$E$3) -> 0.00043 | P9: =O9*J9 -> 0 | Q9: =IF(E9="Paper",Sheet1!$E$8,Sheet1!$E$4) -> 0.00053 | R9: =Q9*J9 -> 0
A10: PPB-9 | B10: Hussain Pulp, Paper and Board Mills Ltd | C10: 23.632741 | D10: 90.469393 | E10: Paper and packaging | G10: Dhaka | H10: Bangladesh | I10: Operating | J10: 0 | K10: =IF(E10="Paper",Sheet1!$E$9,Sheet1!$E$5) -> 0.0013 | L10: =J10*K10 -> 0 | M10: =IF(E10="Paper",Sheet1!$E$6,Sheet1!$E$2) -> 0.000975 | N10: =M10*J10 -> 0 | O10: =IF(E10="Paper",Sheet1!$E$7,Sheet1!$E$3) -> 0.005 | P10: =O10*J10 -> 0 | Q10: =IF(E10="Paper",Sheet1!$E$8,Sheet1!$E$4) -> 0.0025 | R10: =Q10*J10 -> 0
A11: PPB-10 | B11: Khulna Newsprint Mills Ltd | C11: 22.855296 | D11: 89.550998 | E11: Paper | G11: Khalispur | H11: Bangladesh | I11: Operating | J11: 55115.56 | K11: =IF(E11="Paper",Sheet1!$E$9,Sheet1!$E$5) -> 0.000189 | L11: =J11*K11 -> 10.416841 | M11: =IF(E11="Paper",Sheet1!$E$6,Sheet1!$E$2) -> 0.00012285 | N11: =M11*J11 -> 6.7709465 | O11: =IF(E11="Paper",Sheet1!$E$7,Sheet1!$E$3) -> 0.00043 | P11: =O11*J11 -> 23.699691 | Q11: =IF(E11="Paper",Sheet1!$E$8,Sheet1!$E$4) -> 0.00053 | R11: =Q11*J11 -> 29.211247
A12: PPB-11 | B12: Lipy Paper Mills Ltd, Lipy Group | C12: 23.70634 | D12: 90.557929 | E12: Paper | G12: Dhaka | H12: Bangladesh | I12: Operating | J12: 0 | K12: =IF(E12="Paper",Sheet1!$E$9,Sheet1!$E$5) -> 0.000189 | L12: =J12*K12 -> 0 | M12: =IF(E12="Paper",Sheet1!$E$6,Sheet1!$E$2) -> 0.00012285 | N12: =M12*J12 -> 0 | O12: =IF(E12="Paper",Sheet1!$E$7,Sheet1!$E$3) -> 0.00043 | P12: =O12*J12 -> 0 | Q12: =IF(E12="Paper",Sheet1!$E$8,Sheet1!$E$4) -> 0.00053 | R12: =Q12*J12 -> 0
A13: PPB-12 | B13: Magura Paper Mills Ltd, BDG-Magura Group | C13: 23.61567 | D13: 90.61193 | E13: Paper | G13: Dhaka | H13: Bangladesh | I13: Operating | J13: 16534.66 | K13: =IF(E13="Paper",Sheet1!$E$9,Sheet1!$E$5) -> 0.000189 | L13: =J13*K13 -> 3.1250507 | M13: =IF(E13="Paper",Sheet1!$E$6,Sheet1!$E$2) -> 0.00012285 | N13: =M13*J13 -> 2.031283 | O13: =IF(E13="Paper",Sheet1!$E$7,Sheet1!$E$3) -> 0.00043 | P13: =O13*J13 -> 7.1099038 | Q13: =IF(E13="Paper",Sheet1!$E$8,Sheet1!$E$4) -> 0.00053 | R13: =Q13*J13 -> 8.7633698
... A25: PPI-6 | B25: BILT Ballarpur Industries Ltd, Unit Shreegopal | C25: 30.125391 | D25: 77.286179 | E25: Pulp and paper | G25: Yamunanagar | H25: India | I25: Operating | J25: 67000 | K25: =IF(E25="Paper",Sheet1!$E$9,Sheet1!$E$5) -> 0.0013 | L25: =J25*K25 -> 87.1 | M25: =IF(E25="Paper",Sheet1!$E$6,Sheet1!$E$2) -> 0.000975 | N25: =M25*J25 -> 65.325 | O25: =IF(E25="Paper",Sheet1!$E$7,Sheet1!$E$3) -> 0.005 | P25: =O25*J25 -> 335 | Q25: =IF(E25="Paper",Sheet1!$E$8,Sheet1!$E$4) -> 0.0025 | R25: =Q25*J25 -> 167.5
A26: PPI-7 | B26: BILT Ballarpur Industries Ltd | C26: 28.479521 | D26: 77.083474 | E26: pulp and paper | G26: Gurgaon | H26: India | I26: Operating | K26: =IF(E26="Paper",Sheet1!$E$9,Sheet1!$E$5) -> 0.0013 | L26: =J26*K26 -> 0 | M26: =IF(E26="Paper",Sheet1!$E$6,Sheet1!$E$2) -> 0.000975 | N26: =M26*J26 -> 0 | O26: =IF(E26="Paper",Sheet1!$E$7,Sheet1!$E$3) -> 0.005 | P26: =O26*J26 -> 0 | Q26: =IF(E26="Paper",Sheet1!$E$8,Sheet1!$E$4) -> 0.0025 | R26: =Q26*J26 -> 0
A27: PPI-8 | B27: Bindal Papers Limited, Muzaffarnagar Works | C27: 29.471379 | D27: 77.752485 | E27: pulp and paper | G27: Muzaffar Nagar | H27: India | I27: Operating | K27: =IF(E27="Paper",Sheet1!$E$9,Sheet1!$E$5) -> 0.0013 | L27: =J27*K27 -> 0 | M27: =IF(E27="Paper",Sheet1!$E$6,Sheet1!$E$2) -> 0.000975 | N27: =M27*J27 -> 0 | O27: =IF(E27="Paper",Sheet1!$E$7,Sheet1!$E$3) -> 0.005 | P27: =O27*J27 -> 0 | Q27: =IF(E27="Paper",Sheet1!$E$8,Sheet1!$E$4) -> 0.0025 | R27: =Q27*J27 -> 0
A28: PPI-9 | B28: Chandpur Enterprises Ltd | C28: 29.130932 | D28: 78.307016 | E28: Paper | G28: Bijnor | H28: India | I28: Operating | J28: 0 | K28: =IF(E28="Paper",Sheet1!$E$9,Sheet1!$E$5) -> 0.000189 | L28: =J28*K28 -> 0 | M28: =IF(E28="Paper",Sheet1!$E$6,Sheet1!$E$2) -> 0.00012285 | N28: =M28*J28 -> 0 | O28: =IF(E28="Paper",Sheet1!$E$7,Sheet1!$E$3) -> 0.00043 | P28: =O28*J28 -> 0 | Q28: =IF(E28="Paper",Sheet1!$E$8,Sheet1!$E$4) -> 0.00053 | R28: =Q28*J28 -> 0
A29: PPI-10 | B29: Cheema Papers Limited | C29: 27.570589 | D29: 80.098187 | E29: Paper | G29: Naini Tal | H29: India | I29: Operating | J29: 0 | K29: =IF(E29="Paper",Sheet1!$E$9,Sheet1!$E$5) -> 0.000189 | L29: =J29*K29 -> 0 | M29: =IF(E29="Paper",Sheet1!$E$6,Sheet1!$E$2) -> 0.00012285 | N29: =M29*J29 -> 0 | O29: =IF(E29="Paper",Sheet1!$E$7,Sheet1!$E$3) -> 0.00043 | P29: =O29*J29 -> 0 | Q29: =IF(E29="Paper",Sheet1!$E$8,Sheet1!$E$4) -> 0.00053 | R29: =Q29*J29 -> 0
A30: PPI-11 | B30: Chemopulp Tissues Limited | C30: 28.738847 | D30: 77.262262 | E30: Paper | G30: Ghaziabad | H30: India | I30: Operating | J30: 0 | K30: =IF(E30="Paper",Sheet1!$E$9,Sheet1!$E$5) -> 0.000189 | L30: =J30*K30 -> 0 | M30: =IF(E30="Paper",Sheet1!$E$6,Sheet1!$E$2) -> 0.00012285 | N30: =M30*J30 -> 0 | O30: =IF(E30="Paper",Sheet1!$E$7,Sheet1!$E$3) -> 0.00043 | P30: =O30*J30 -> 0 | Q30: =IF(E30="Paper",Sheet1!$E$8,Sheet1!$E$4) -> 0.00053 | R30: =Q30*J30 -> 0
A31: PPI-12 | B31: CPP Century Pulp & Paper | C31: 28.53952 | D31: 77.289257 | E31: Paper | G31: Delhi | H31: India | I31: Operating | J31: 0 | K31: =IF(E31="Paper",Sheet1!$E$9,Sheet1!$E$5) -> 0.000189 | L31: =J31*K31 -> 0 | M31: =IF(E31="Paper",Sheet1!$E$6,Sheet1!$E$2) -> 0.00012285 | N31: =M31*J31 -> 0 | O31: =IF(E31="Paper",Sheet1!$E$7,Sheet1!$E$3) -> 0.00043 | P31: =O31*J31 -> 0 | Q31: =IF(E31="Paper",Sheet1!$E$8,Sheet1!$E$4) -> 0.00053 | R31: =Q31*J31 -> 0
A32: PPI-13 | B32: East India Paper & Board Mills | C32: 22.549349 | D32: 88.357539 | E32: Paper and packaging | G32: Kolkata | H32: India | I32: Operating | J32: 0 | K32: =IF(E32="Paper",Sheet1!$E$9,Sheet1!$E$5) -> 0.0013 | L32: =J32*K32 -> 0 | M32: =IF(E32="Paper",Sheet1!$E$6,Sheet1!$E$2) -> 0.000975 | N32: =M32*J32 -> 0 | O32: =IF(E32="Paper",Sheet1!$E$7,Sheet1!$E$3) -> 0.005 | P32: =O32*J32 -> 0 | Q32: =IF(E32="Paper",Sheet1!$E$8,Sheet1!$E$4) -> 0.0025 | R32: =Q32*J32 -> 0
A33: PPI-14 | B33: Gateway Speciality Papers Limited | C33: 28.702227 | D33: 77.173583 | E33: Paper | G33: Delhi | H33: India | I33: Operating | J33: 0 | K33: =IF(E33="Paper",Sheet1!$E$9,Sheet1!$E$5) -> 0.000189 | L33: =J33*K33 -> 0 | M33: =IF(E33="Paper",Sheet1!$E$6,Sheet1!$E$2) -> 0.00012285 | N33: =M33*J33 -> 0 | O33: =IF(E33="Paper",Sheet1!$E$7,Sheet1!$E$3) -> 0.00043 | P33: =O33*J33 -> 0 | Q33: =IF(E33="Paper",Sheet1!$E$8,Sheet1!$E$4) -> 0.00053 | R33: =Q33*J33 -> 0
A34: PPI-15 | B34: Gateway Speciality Papers Limited, Kundli Mill | C34: 28.807261 | D34: 77.140421 | E34: Paper | G34: Kundli | H34: India | I34: Operating | J34: 0 | K34: =IF(E34="Paper",Sheet1!$E$9,Sheet1!$E$5) -> 0.000189 | L34: =J34*K34 -> 0 | M34: =IF(E34="Paper",Sheet1!$E$6,Sheet1!$E$2) -> 0.00012285 | N34: =M34*J34 -> 0 | O34: =IF(E34="Paper",Sheet1!$E$7,Sheet1!$E$3) -> 0.00043 | P34: =O34*J34 -> 0 | Q34: =IF(E34="Paper",Sheet1!$E$8,Sheet1!$E$4) -> 0.00053 | R34: =Q34*J34 -> 0
A35: PPI-16 | B35: Incite Homecare Products (P) Limited, Regional Office Noida | C35: 28.580386 | D35: 77.244269 | E35: pulp and paper | G35: Noida | H35: India | I35: Operating | J35: 0 | K35: =IF(E35="Paper",Sheet1!$E$9,Sheet1!$E$5) -> 0.0013 | L35: =J35*K35 -> 0 | M35: =IF(E35="Paper",Sheet1!$E$6,Sheet1!$E$2) -> 0.000975 | N35: =M35*J35 -> 0 | O35: =IF(E35="Paper",Sheet1!$E$7,Sheet1!$E$3) -> 0.005 | P35: =O35*J35 -> 0 | Q35: =IF(E35="Paper",Sheet1!$E$8,Sheet1!$E$4) -> 0.0025 | R35: =Q35*J35 -> 0
A36: PPI-17 | B36: ITC Limited, Registered Office | C36: 22.551246 | D36: 88.349185 | E36: pulp and paper | G36: Kolkata | H36: India | I36: Operating | J36: 0 | K36: =IF(E36="Paper",Sheet1!$E$9,Sheet1!$E$5) -> 0.0013 | L36: =J36*K36 -> 0 | M36: =IF(E36="Paper",Sheet1!$E$6,Sheet1!$E$2) -> 0.000975 | N36: =M36*J36 -> 0 | O36: =IF(E36="Paper",Sheet1!$E$7,Sheet1!$E$3) -> 0.005 | P36: =O36*J36 -> 0 | Q36: =IF(E36="Paper",Sheet1!$E$8,Sheet1!$E$4) -> 0.0025 | R36: =Q36*J36 -> 0
A37: PPI-18 | B37: Krishna Tissues Private Limited, Corporate Office | C37: 22.590272 | D37: 88.404164 | E37: pulp and paper | G37: Kolkata | H37: India | I37: Operating | J37: 0 | K37: =IF(E37="Paper",Sheet1!$E$9,Sheet1!$E$5) -> 0.0013 | L37: =J37*K37 -> 0 | M37: =IF(E37="Paper",Sheet1!$E$6,Sheet1!$E$2) -> 0.000975 | N37: =M37*J37 -> 0 | O37: =IF(E37="Paper",Sheet1!$E$7,Sheet1!$E$3) -> 0.005 | P37: =O37*J37 -> 0 | Q37: =IF(E37="Paper",Sheet1!$E$8,Sheet1!$E$4) -> 0.0025 | R37: =Q37*J37 -> 0
A38: PPI-19 | B38: Kuantum Papers Ltd, Corporate Office | C38: 30.73754 | D38: 76.793495 | E38: pulp and paper | G38: Chandigarh | H38: India | I38: Operating | J38: 0 | K38: =IF(E38="Paper",Sheet1!$E$9,Sheet1!$E$5) -> 0.0013 | L38: =J38*K38 -> 0 | M38: =IF(E38="Paper",Sheet1!$E$6,Sheet1!$E$2) -> 0.000975 | N38: =M38*J38 -> 0 | O38: =IF(E38="Paper",Sheet1!$E$7,Sheet1!$E$3) -> 0.005 | P38: =O38*J38 -> 0 | Q38: =IF(E38="Paper",Sheet1!$E$8,Sheet1!$E$4) -> 0.0025 | R38: =Q38*J38 -> 0
A39: PPI-20 | B39: Hanuman Chromocoates Limited | C39: 22.571265 | D39: 88.345866 | E39: Paper | G39: Kolkata | H39: India | I39: Operating | J39: 0 | K39: =IF(E39="Paper",Sheet1!$E$9,Sheet1!$E$5) -> 0.000189 | L39: =J39*K39 -> 0 | M39: =IF(E39="Paper",Sheet1!$E$6,Sheet1!$E$2) -> 0.00012285 | N39: =M39*J39 -> 0 | O39: =IF(E39="Paper",Sheet1!$E$7,Sheet1!$E$3) -> 0.00043 | P39: =O39*J39 -> 0 | Q39: =IF(E39="Paper",Sheet1!$E$8,Sheet1!$E$4) -> 0.00053 | R39: =Q39*J39 -> 0
... A92: PPP-13 | B92: Flying Kraft Paper Mills Ltd, A company of Flying Group of Companies | C92: 34.168181 | D92: 71.750385 | E92: Pulp and paper | G92: Charsadda | H92: Pakistan | I92: Operating | J92: 66000 | K92: =IF(E92="Paper",Sheet1!$E$9,Sheet1!$E$5) -> 0.0013 | L92: =J92*K92 -> 85.8 | M92: =IF(E92="Paper",Sheet1!$E$6,Sheet1!$E$2) -> 0.000975 | N92: =M92*J92 -> 64.35 | O92: =IF(E92="Paper",Sheet1!$E$7,Sheet1!$E$3) -> 0.005 | P92: =O92*J92 -> 330 | Q92: =IF(E92="Paper",Sheet1!$E$8,Sheet1!$E$4) -> 0.0025 | R92: =Q92*J92 -> 165
A93: PPP-14 | B93: Flying Paper Industries Ltd, A company of Flying Group of Companies | C93: 31.524793 | D93: 74.322561 | G93: Lahore | H93: Pakistan | I93: Operating | J93: 0 | K93: =IF(E93="Paper",Sheet1!$E$9,Sheet1!$E$5) -> 0.0013 | L93: =J93*K93 -> 0 | M93: =IF(E93="Paper",Sheet1!$E$6,Sheet1!$E$2) -> 0.000975 | N93: =M93*J93 -> 0 | O93: =IF(E93="Paper",Sheet1!$E$7,Sheet1!$E$3) -> 0.005 | P93: =O93*J93 -> 0 | Q93: =IF(E93="Paper",Sheet1!$E$8,Sheet1!$E$4) -> 0.0025 | R93: =Q93*J93 -> 0
A94: PPP-15 | B94: Jubilee Paper Board Mills Limited | C94: 31.989488 | D94: 74.219553 | E94: Pulp and paper and packaging | G94: Kamoke | H94: Pakistan | I94: Operating | J94: 10000 | K94: =IF(E94="Paper",Sheet1!$E$9,Sheet1!$E$5) -> 0.0013 | L94: =J94*K94 -> 13 | M94: =IF(E94="Paper",Sheet1!$E$6,Sheet1!$E$2) -> 0.000975 | N94: =M94*J94 -> 9.75 | O94: =IF(E94="Paper",Sheet1!$E$7,Sheet1!$E$3) -> 0.005 | P94: =O94*J94 -> 50 | Q94: =IF(E94="Paper",Sheet1!$E$8,Sheet1!$E$4) -> 0.0025 | R94: =Q94*J94 -> 25
A95: PPP-16 | B95: Karachi Paper and Board Mills | C95: 24.84334 | D95: 67.152721 | E95: Paper | G95: Karachi | H95: Pakistan | I95: Operating | J95: 0 | K95: =IF(E95="Paper",Sheet1!$E$9,Sheet1!$E$5) -> 0.000189 | L95: =J95*K95 -> 0 | M95: =IF(E95="Paper",Sheet1!$E$6,Sheet1!$E$2) -> 0.00012285 | N95: =M95*J95 -> 0 | O95: =IF(E95="Paper",Sheet1!$E$7,Sheet1!$E$3) -> 0.00043 | P95: =O95*J95 -> 0 | Q95: =IF(E95="Paper",Sheet1!$E$8,Sheet1!$E$4) -> 0.00053 | R95: =Q95*J95 -> 0
A96: PPP-17 | B96: Lucky Paper Mill | C96: 25.354252 | D96: 68.275088 | E96: Paper and packaging | G96: Jamshoro | H96: Pakistan | I96: Operating | J96: 0 | K96: =IF(E96="Paper",Sheet1!$E$9,Sheet1!$E$5) -> 0.0013 | L96: =J96*K96 -> 0 | M96: =IF(E96="Paper",Sheet1!$E$6,Sheet1!$E$2) -> 0.000975 | N96: =M96*J96 -> 0 | O96: =IF(E96="Paper",Sheet1!$E$7,Sheet1!$E$3) -> 0.005 | P96: =O96*J96 -> 0 | Q96: =IF(E96="Paper",Sheet1!$E$8,Sheet1!$E$4) -> 0.0025 | R96: =Q96*J96 -> 0
A97: PPP-18 | B97: Malik Board and Paper Industries (Pvt) Ltd | C97: 31.487165 | D97: 74.347071 | E97: Paper and packaging | G97: Lahore | H97: Pakistan | I97: Operating | J97: 0 | K97: =IF(E97="Paper",Sheet1!$E$9,Sheet1!$E$5) -> 0.0013 | L97: =J97*K97 -> 0 | M97: =IF(E97="Paper",Sheet1!$E$6,Sheet1!$E$2) -> 0.000975 | N97: =M97*J97 -> 0 | O97: =IF(E97="Paper",Sheet1!$E$7,Sheet1!$E$3) -> 0.005 | P97: =O97*J97 -> 0 | Q97: =IF(E97="Paper",Sheet1!$E$8,Sheet1!$E$4) -> 0.0025 | R97: =Q97*J97 -> 0
A98: PPP-19 | B98: Mandiali Paper Mills (Pvt) Ltd | C98: 31.660477 | D98: 74.148974 | E98: Pulp and paper | G98: Sheikhupura | H98: Pakistan | I98: Operating | J98: 0 | K98: =IF(E98="Paper",Sheet1!$E$9,Sheet1!$E$5) -> 0.0013 | L98: =J98*K98 -> 0 | M98: =IF(E98="Paper",Sheet1!$E$6,Sheet1!$E$2) -> 0.000975 | N98: =M98*J98 -> 0 | O98: =IF(E98="Paper",Sheet1!$E$7,Sheet1!$E$3) -> 0.005 | P98: =O98*J98 -> 0 | Q98: =IF(E98="Paper",Sheet1!$E$8,Sheet1!$E$4) -> 0.0025 | R98: =Q98*J98 -> 0
A99: PPP-20 | B99: Orient Straw Board & Paper Mills Ltd | C99: 24.857675 | D99: 67.003011 | E99: Pulp and paper | G99: Karachi | H99: Pakistan | I99: Operating | J99: 7500 | K99: =IF(E99="Paper",Sheet1!$E$9,Sheet1!$E$5) -> 0.0013 | L99: =J99*K99 -> 9.75 | M99: =IF(E99="Paper",Sheet1!$E$6,Sheet1!$E$2) -> 0.000975 | N99: =M99*J99 -> 7.3125 | O99: =IF(E99="Paper",Sheet1!$E$7,Sheet1!$E$3) -> 0.005 | P99: =O99*J99 -> 37.5 | Q99: =IF(E99="Paper",Sheet1!$E$8,Sheet1!$E$4) -> 0.0025 | R99: =Q99*J99 -> 18.75
A100: PPP-21 | B100: Packages Ltd | C100: 31.469508 | D100: 74.349841 | E100: Pulp and paper and packaging | G100: Lahore | H100: Pakistan | I100: Operating | J100: 94000 | K100: =IF(E100="Paper",Sheet1!$E$9,Sheet1!$E$5) -> 0.0013 | L100: =J100*K100 -> 122.2 | M100: =IF(E100="Paper",Sheet1!$E$6,Sheet1!$E$2) -> 0.000975 | N100: =M100*J100 -> 91.65 | O100: =IF(E100="Paper",Sheet1!$E$7,Sheet1!$E$3) -> 0.005 | P100: =O100*J100 -> 470 | Q100: =IF(E100="Paper",Sheet1!$E$8,Sheet1!$E$4) -> 0.0025 | R100: =Q100*J100 -> 235
A101: PPP-22 | B101: Pakistan Paper Products | C101: 24.900312 | D101: 66.991229 | E101: Packaging | G101: Karachi | H101: Pakistan | I101: Operating | J101: 0 | K101: =IF(E101="Paper",Sheet1!$E$9,Sheet1!$E$5) -> 0.0013 | L101: =J101*K101 -> 0 | M101: =IF(E101="Paper",Sheet1!$E$6,Sheet1!$E$2) -> 0.000975 | N101: =M101*J101 -> 0 | O101: =IF(E101="Paper",Sheet1!$E$7,Sheet1!$E$3) -> 0.005 | P101: =O101*J101 -> 0 | Q101: =IF(E101="Paper",Sheet1!$E$8,Sheet1!$E$4) -> 0.0025 | R101: =Q101*J101 -> 0
A102: PPP-23 | B102: Paper International Ltd | C102: 34.005787 | D102: 71.929666 | E102: pulp and paper | G102: Nowshera | H102: Pakistan | I102: Operating | J102: 0 | K102: =IF(E102="Paper",Sheet1!$E$9,Sheet1!$E$5) -> 0.0013 | L102: =J102*K102 -> 0 | M102: =IF(E102="Paper",Sheet1!$E$6,Sheet1!$E$2) -> 0.000975 | N102: =M102*J102 -> 0 | O102: =IF(E102="Paper",Sheet1!$E$7,Sheet1!$E$3) -> 0.005 | P102: =O102*J102 -> 0 | Q102: =IF(E102="Paper",Sheet1!$E$8,Sheet1!$E$4) -> 0.0025 | R102: =Q102*J102 -> 0
A103: PPP-24 | B103: Pioneer Board | C103: 31.396276 | D103: 74.14581 | E103: Packaging | G103: Lahore | H103: Pakistan | I103: Operating | J103: 0 | K103: =IF(E103="Paper",Sheet1!$E$9,Sheet1!$E$5) -> 0.0013 | L103: =J103*K103 -> 0 | M103: =IF(E103="Paper",Sheet1!$E$6,Sheet1!$E$2) -> 0.000975 | N103: =M103*J103 -> 0 | O103: =IF(E103="Paper",Sheet1!$E$7,Sheet1!$E$3) -> 0.005 | P103: =O103*J103 -> 0 | Q103: =IF(E103="Paper",Sheet1!$E$8,Sheet1!$E$4) -> 0.0025 | R103: =Q103*J103 -> 0
...

Sheet Sheet1
A1: Pollutant | B1: type | C1: EF | D1: Unit | E1: EF normalised (tonnes of pollutant/tonnes of production) | F1: Notes
A2: PM2.5 | B2: paper and pulp | C2: 0.975 | D2: tonne/000 tonnes | E2: =C2/1000 -> 0.000975 | F2: Following common empirical relationships PM₁₀ was estimated as 0.6 × PM and PM₂.₅ as 0.65 × PM₁₀.
A3: SO2 | B3: paper and pulp | C3: 5 | D3: tonne/000 tonnes | E3: =C3/1000 -> 0.005
A4: NOx | B4: paper and pulp | C4: 2.5 | D4: tonne/000 tonnes | E4: =C4/1000 -> 0.0025
A5: PM10* | B5: paper and pulp | C5: 1.3 | D5: tonne/000 tonnes | E5: =C5/1000 -> 0.0013
A6: PM2.5 | B6: paper | C6: =0.65*C9 -> 0.12285 | D6: tonne/000 tonnes | E6: =C6/1000 -> 0.00012285
A7: SO2 | B7: paper | C7: 0.43 | D7: tonne/000 tonnes | E7: =C7/1000 -> 0.00043
A8: NOx | B8: paper | C8: 0.53 | D8: tonne/000 tonnes | E8: =C8/1000 -> 0.00053
A9: PM10* | B9: paper | C9: =0.6*0.315 -> 0.189 | D9: tonne/000 tonnes | E9: =C9/1000 -> 0.000189
A14: Source | C14: https://www.eea.europa.eu/en/analysis/publications/emep-eea-guidebook-2023/part-b-sectoral-guidance-chapters/2-industrial-processes-and-product-use/2-h-other-industry-production/2-h-1-pulp-and/@@download/file | E14: This paper is used to extract Efs for paper and pulp type of plants
C15: Bordado, J. C., & Gomes, J. F. (1997). Pollutant atmospheric emissions from Portuguese Kraft pulp mills. Science of the total environment, 208(1-2), 139-143. | E15: Whereas, this paper helps find the EFs only for paper production. In this paper they only mention PM = 0.315, therefore we use some factoring to estimate PM2.5 and PM10
